Workbook

Sheet RAW
A1: =MAX(B2:DY129) -> 254.39 | B1: 0 | F1: 1 | J1: 2 | N1: 3 | R1: 4 | V1: 5 | Z1: 6 | AD1: 7 | AH1: 8 | AL1: 9 | AP1: 10 | AT1: 11 | AX1: 12 | BB1: 13 | BF1: 14 | BJ1: 15 | BN1: 16 | BR1: 17 | BV1: 18 | BZ1: 19 | CD1: 20 | CH1: 21 | CL1: 22 | CP1: 23 | CT1: 24 | CX1: 25 | DB1: 26 | DF1: 27 | DJ1: 28 | DN1: 29 | DR1: 30 | DV1: 31
A2: 0 | B2: 19.23 | C2: 17.47 | D2: 18.48 | E2: 18.08 | F2: 20.31 | G2: 23.97 | H2: 21.12 | I2: 20.52 | J2: 17.88 | K2: 22.34 | L2: 26.81 | M2: 31.08 | N2: 34.97 | O2: 24.38 | P2: 19.5 | Q2: 20.72 | R2: 17.67 | S2: 18.89 | T2: 21.73 | U2: 23.36 | V2: 21.94 | W2: 19.3 | X2: 20.11 | Y2: 16.86 | Z2: 15.84 | AA2: 17.28 | AB2: 37.31 | AC2: 33.52 | AD2: 42.91 | AE2: 46.16 | AF2: 39.61 | AG2: 34.94 | AH2: 31.89 | AI2: 33.34 | AJ2: 32.94 | AK2: 23.16 | AL2: 19.3 | AM2: 21.94 | AN2: 19.7 | AO2: 17.67 | AP2: 17.88 | AQ2: 16.86 | AR2: 17.06 | AS2: 17.47 | AT2: 15.64 | AU2: 14.22 | AV2: 16.25 | AW2: 16.25 | AX2: 26.64 | AY2: 15.84 | AZ2: 18.69 | BA2: 21.33 | BB2: 20.31 | BC2: 19.7 | BD2: 20.31 | BE2: 21.73 | BF2: 23.97 | BG2: 22.55 | BH2: 20.72 | BI2: 19.09 | BJ2: 19.09 | BK2: 19.7 | BL2: 22.14 | BM2: 19.09 | BN2: 22.55 | BO2: 18.89 | BP2: 18.08 | BQ2: 19.09 | BR2: 17.06 | BS2: 18.08 | BT2: 16.45 | BU2: 17.06 | BV2: 17.06 | BW2: 15.23 | BX2: 17.27 | BY2: 19.3 | BZ2: 32.31 | CA2: 87.05 | CB2: 111.81 | CC2: 70.56 | CD2: 88 | CE2: 36.83 | CF2: 21.94 | CG2: 19.91 | CH2: 21.33 | CI2: 21.73 | CJ2: 19.09 | CK2: 19.91 | CL2: 25.42 | CM2: 27.75 | CN2: 22.56 | CO2: 31.92 | CP2: 44.02 | CQ2: 108 | CR2: 50.23 | CS2: 22.14 | CT2: 20.72 | CU2: 17.67 | CV2: 20.92 | CW2: 19.09 | CX2: 18.28 | CY2: 21.73 | CZ2: 19.91 | DA2: 26.41 | DB2: 37.03 | DC2: 154.12 | DD2: 99.64 | DE2: 77.88 | DF2: 32.92 | DG2: 23.97 | DH2: 20.31 | DI2: 20.72 | DJ2: 20.11 | DK2: 19.5 | DL2: 22.75 | DM2: 19.7 | DN2: 15.64 | DO2: 16.25 | DP2: 14.02 | DQ2: 15.84 | DR2: 13.61 | DS2: 15.64 | DT2: 16.05 | DU2: 19.09 | DV2: 16.86 | DW2: 21.73 | DX2: 18.69 | DY2: 18.83
B3: 18.22 | C3: 18.08 | D3: 18.69 | E3: 17.06 | F3: 19.7 | G3: 20.11 | H3: 21.53 | I3: 18.69 | J3: 20.72 | K3: 22.14 | L3: 26.61 | M3: 34.73 | N3: 30.47 | O3: 20.92 | P3: 17.47 | Q3: 16.86 | R3: 17.67 | S3: 19.3 | T3: 18.08 | U3: 21.73 | V3: 22.14 | W3: 21.94 | X3: 23.97 | Y3: 18.28 | Z3: 16.45 | AA3: 19.7 | AB3: 28.03 | AC3: 43.72 | AD3: 41.25 | AE3: 30.88 | AF3: 33.53 | AG3: 33.72 | AH3: 33.12 | AI3: 34.53 | AJ3: 38.2 | AK3: 38.81 | AL3: 31.09 | AM3: 23.16 | AN3: 22.34 | AO3: 20.11 | AP3: 18.69 | AQ3: 18.89 | AR3: 19.7 | AS3: 16.86 | AT3: 18.69 | AU3: 19.5 | AV3: 16.66 | AW3: 16.25 | AX3: 16.86 | AY3: 16.86 | AZ3: 18.08 | BA3: 17.47 | BB3: 17.47 | BC3: 18.91 | BD3: 18.89 | BE3: 20.92 | BF3: 19.3 | BG3: 18.89 | BH3: 18.28 | BI3: 18.69 | BJ3: 19.5 | BK3: 20.72 | BL3: 22.95 | BM3: 23.36 | BN3: 22.34 | BO3: 21.94 | BP3: 16.66 | BQ3: 17.88 | BR3: 15.44 | BS3: 17.27 | BT3: 16.25 | BU3: 19.5 | BV3: 16.45 | BW3: 20.52 | BX3: 25.83 | BY3: 22.14 | BZ3: 52.83 | CA3: 108.25 | CB3: 104.06 | CC3: 81.75 | CD3: 77.25 | CE3: 28.45 | CF3: 21.53 | CG3: 19.7 | CH3: 20.11 | CI3: 17.67 | CJ3: 18.89 | CK3: 17.67 | CL3: 19.7 | CM3: 18.89 | CN3: 20.52 | CO3: 22.34 | CP3: 47.33 | CQ3: 68.47 | CR3: 31.92 | CS3: 20.31 | CT3: 18.28 | CU3: 18.89 | CV3: 17.47 | CW3: 20.11 | CX3: 20.72 | CY3: 36.7 | CZ3: 64.66 | DA3: 93.92 | DB3: 143.94 | DC3: 194.58 | DD3: 57.53 | DE3: 76.38 | DF3: 32.73 | DG3: 24.78 | DH3: 21.53 | DI3: 23.36 | DJ3: 20.92 | DK3: 23.77 | DL3: 21.53 | DM3: 21.33 | DN3: 18.69 | DO3: 18.28 | DP3: 15.44 | DQ3: 17.88 | DR3: 15.84 | DS3: 16.05 | DT3: 16.66 | DU3: 17.27 | DV3: 16.86 | DW3: 18.28 | DX3: 17.67 | DY3: 17.2
B4: 17.81 | C4: 20.11 | D4: 19.3 | E4: 19.5 | F4: 18.89 | G4: 19.7 | H4: 24.58 | I4: 19.09 | J4: 20.72 | K4: 20.11 | L4: 29.66 | M4: 44.97 | N4: 28.84 | O4: 21.12 | P4: 18.48 | Q4: 16.66 | R4: 17.67 | S4: 17.27 | T4: 19.5 | U4: 19.09 | V4: 21.33 | W4: 24.58 | X4: 20.11 | Y4: 19.3 | Z4: 20.52 | AA4: 24.78 | AB4: 37.8 | AC4: 42.69 | AD4: 31.91 | AE4: 22.55 | AF4: 21.12 | AG4: 23.56 | AH4: 27.42 | AI4: 33.52 | AJ4: 40.47 | AK4: 44.12 | AL4: 48.89 | AM4: 39.08 | AN4: 32.53 | AO4: 26.2 | AP4: 22.75 | AQ4: 22.14 | AR4: 20.31 | AS4: 20.52 | AT4: 22.14 | AU4: 23.16 | AV4: 18.28 | AW4: 17.67 | AX4: 17.47 | AY4: 16.45 | AZ4: 18.89 | BA4: 17.47 | BB4: 16.45 | BC4: 17.88 | BD4: 16.86 | BE4: 19.7 | BF4: 16.45 | BG4: 16.25 | BH4: 18.28 | BI4: 19.7 | BJ4: 20.11 | BK4: 21.94 | BL4: 23.77 | BM4: 24.38 | BN4: 23.36 | BO4: 24.58 | BP4: 19.91 | BQ4: 18.28 | BR4: 15.44 | BS4: 15.64 | BT4: 16.05 | BU4: 18.69 | BV4: 17.27 | BW4: 18.89 | BX4: 24.38 | BY4: 35.39 | BZ4: 85.55 | CA4: 114.3 | CB4: 87 | CC4: 85.98 | CD4: 50.41 | CE4: 22.95 | CF4: 20.52 | CG4: 20.92 | CH4: 19.3 | CI4: 18.48 | CJ4: 17.67 | CK4: 16.86 | CL4: 18.48 | CM4: 19.09 | CN4: 20.92 | CO4: 19.5 | CP4: 29.69 | CQ4: 39.92 | CR4: 20.72 | CS4: 17.47 | CT4: 18.28 | CU4: 19.3 | CV4: 18.28 | CW4: 20.52 | CX4: 24.38 | CY4: 57.2 | CZ4: 55.27 | DA4: 61.44 | DB4: 154.14 | DC4: 174.75 | DD4: 69.94 | DE4: 90.5 | DF4: 38.81 | DG4: 26.61 | DH4: 24.78 | DI4: 23.36 | DJ4: 22.75 | DK4: 24.78 | DL4: 23.97 | DM4: 22.34 | DN4: 19.7 | DO4: 19.91 | DP4: 19.52 | DQ4: 17.27 | DR4: 16.05 | DS4: 15.44 | DT4: 18.91 | DU4: 19.75 | DV4: 15.64 | DW4: 16.05 | DX4: 17.47 | DY4: 18.22
B5: 17.2 | C5: 19.09 | D5: 19.3 | E5: 19.91 | F5: 19.3 | G5: 19.3 | H5: 18.89 | I5: 18.28 | J5: 17.47 | K5: 22.55 | L5: 39.28 | M5: 44.52 | N5: 25.39 | O5: 21.12 | P5: 20.92 | Q5: 20.11 | R5: 19.7 | S5: 18.69 | T5: 18.89 | U5: 20.92 | V5: 21.33 | W5: 23.77 | X5: 21.33 | Y5: 21.33 | Z5: 22.34 | AA5: 37.78 | AB5: 53.61 | AC5: 33.95 | AD5: 26.41 | AE5: 20.92 | AF5: 23.16 | AG5: 21.12 | AH5: 20.72 | AI5: 22.34 | AJ5: 24.17 | AK5: 35.78 | AL5: 53.02 | AM5: 61 | AN5: 71.16 | AO5: 66.27 | AP5: 50.78 | AQ5: 29.45 | AR5: 21.94 | AS5: 21.33 | AT5: 22.34 | AU5: 21.53 | AV5: 20.52 | AW5: 20.52 | AX5: 19.09 | AY5: 16.25 | AZ5: 18.69 | BA5: 19.7 | BB5: 17.06 | BC5: 16.86 | BD5: 16.45 | BE5: 13.61 | BF5: 15.84 | BG5: 17.27 | BH5: 20.11 | BI5: 21.33 | BJ5: 20.92 | BK5: 21.12 | BL5: 21.12 | BM5: 24.17 | BN5: 23.16 | BO5: 17.88 | BP5: 17.47 | BQ5: 26.88 | BR5: 14.83 | BS5: 14.83 | BT5: 16.25 | BU5: 14.83 | BV5: 19.3 | BW5: 20.11 | BX5: 27.42 | BY5: 69.39 | BZ5: 113.67 | CA5: 106.55 | CB5: 90.53 | CC5: 66.91 | CD5: 26.61 | CE5: 22.75 | CF5: 27.44 | CG5: 23.97 | CH5: 19.91 | CI5: 16.25 | CJ5: 16.25 | CK5: 19.3 | CL5: 18.89 | CM5: 17.88 | CN5: 20.11 | CO5: 20.11 | CP5: 18.08 | CQ5: 18.28 | CR5: 18.69 | CS5: 19.5 | CT5: 19.09 | CU5: 18.08 | CV5: 18.08 | CW5: 18.28 | CX5: 26.61 | CY5: 30.69 | CZ5: 50.31 | DA5: 82.84 | DB5: 191 | DC5: 101.88 | DD5: 83.47 | DE5: 95.34 | DF5: 44.12 | DG5: 24.98 | DH5: 25.39 | DI5: 21.94 | DJ5: 21.53 | DK5: 22.95 | DL5: 25 | DM5: 20.72 | DN5: 20.72 | DO5: 20.31 | DP5: 17.47 | DQ5: 18.08 | DR5: 16.05 | DS5: 15.64 | DT5: 16.25 | DU5: 16.86 | DV5: 16.25 | DW5: 15.84 | DX5: 22.34 | DY5: 19.23
A6: 1 | B6: 21.45 | C6: 21.33 | D6: 19.09 | E6: 20.31 | F6: 17.88 | G6: 19.3 | H6: 17.67 | I6: 17.47 | J6: 20.11 | K6: 26 | L6: 54.78 | M6: 41.89 | N6: 22.75 | O6: 22.14 | P6: 22.95 | Q6: 23.56 | R6: 20.52 | S6: 20.11 | T6: 20.52 | U6: 20.11 | V6: 20.92 | W6: 21.73 | X6: 20.92 | Y6: 26.41 | Z6: 38.03 | AA6: 46.97 | AB6: 40.64 | AC6: 35.95 | AD6: 29.05 | AE6: 25.39 | AF6: 23.77 | AG6: 21.33 | AH6: 20.11 | AI6: 20.72 | AJ6: 19.91 | AK6: 19.5 | AL6: 26.2 | AM6: 32.92 | AN6: 43.98 | AO6: 69.61 | AP6: 90.47 | AQ6: 56.73 | AR6: 29.05 | AS6: 25.59 | AT6: 22.55 | AU6: 22.34 | AV6: 21.73 | AW6: 22.75 | AX6: 19.3 | AY6: 19.5 | AZ6: 20.11 | BA6: 17.47 | BB6: 19.91 | BC6: 17.47 | BD6: 18.28 | BE6: 18.28 | BF6: 16.25 | BG6: 16.66 | BH6: 17.88 | BI6: 18.08 | BJ6: 18.48 | BK6: 19.3 | BL6: 21.33 | BM6: 19.91 | BN6: 22.34 | BO6: 20.73 | BP6: 17.47 | BQ6: 23.19 | BR6: 15.03 | BS6: 15.44 | BT6: 14.42 | BU6: 17.67 | BV6: 18.28 | BW6: 28.25 | BX6: 66.88 | BY6: 108.02 | BZ6: 115.75 | CA6: 95.34 | CB6: 73.48 | CC6: 30.88 | CD6: 25.39 | CE6: 21.53 | CF6: 25.19 | CG6: 21.12 | CH6: 17.88 | CI6: 14.83 | CJ6: 16.25 | CK6: 15.03 | CL6: 17.47 | CM6: 18.48 | CN6: 18.69 | CO6: 18.28 | CP6: 19.31 | CQ6: 17.47 | CR6: 19.3 | CS6: 18.28 | CT6: 17.06 | CU6: 16.05 | CV6: 16.66 | CW6: 25.03 | CX6: 20.52 | CY6: 40.25 | CZ6: 50.16 | DA6: 105.12 | DB6: 73.97 | DC6: 57.97 | DD6: 61.66 | DE6: 59.58 | DF6: 33.73 | DG6: 25.39 | DH6: 25.19 | DI6: 23.16 | DJ6: 20.11 | DK6: 18.89 | DL6: 18.28 | DM6: 18.69 | DN6: 20.11 | DO6: 22.75 | DP6: 20.92 | DQ6: 20.11 | DR6: 20.11 | DS6: 17.88 | DT6: 16.86 | DU6: 20.33 | DV6: 16.86 | DW6: 17.67 | DX6: 18.48 | DY6: 20.25
B7: 20.05 | C7: 18.89 | D7: 20.52 | E7: 17.88 | F7: 19.09 | G7: 19.09 | H7: 17.47 | I7: 17.47 | J7: 20.31 | K7: 37.62 | L7: 59.72 | M7: 34.55 | N7: 24.38 | O7: 20.31 | P7: 20.92 | Q7: 21.73 | R7: 20.52 | S7: 24.38 | T7: 22.34 | U7: 22.75 | V7: 22.95 | W7: 23.36 | X7: 30.48 | Y7: 44.75 | Z7: 49.84 | AA7: 47.17 | AB7: 34.33 | AC7: 38.2 | AD7: 33.31 | AE7: 24.98 | AF7: 24.17 | AG7: 23.36 | AH7: 20.31 | AI7: 21.33 | AJ7: 18.48 | AK7: 19.91 | AL7: 18.08 | AM7: 19.09 | AN7: 21.73 | AO7: 30.06 | AP7: 59.84 | AQ7: 77.45 | AR7: 48.45 | AS7: 28.64 | AT7: 26.2 | AU7: 24.38 | AV7: 21.12 | AW7: 21.33 | AX7: 20.72 | AY7: 20.11 | AZ7: 18.89 | BA7: 17.88 | BB7: 19.5 | BC7: 21.12 | BD7: 19.3 | BE7: 19.5 | BF7: 18.69 | BG7: 18.48 | BH7: 19.7 | BI7: 19.91 | BJ7: 18.08 | BK7: 19.3 | BL7: 18.69 | BM7: 18.48 | BN7: 21.33 | BO7: 18.69 | BP7: 15.64 | BQ7: 15.64 | BR7: 14.42 | BS7: 15.44 | BT7: 16.66 | BU7: 18.89 | BV7: 25.44 | BW7: 60.88 | BX7: 97.61 | BY7: 126.03 | BZ7: 105.06 | CA7: 76.8 | CB7: 36.61 | CC7: 23.36 | CD7: 22.14 | CE7: 21.73 | CF7: 19.09 | CG7: 20.52 | CH7: 19.09 | CI7: 17.88 | CJ7: 17.06 | CK7: 16.25 | CL7: 18.08 | CM7: 20.92 | CN7: 17.88 | CO7: 16.66 | CP7: 19.3 | CQ7: 17.67 | CR7: 17.67 | CS7: 17.47 | CT7: 19.5 | CU7: 18.28 | CV7: 16.86 | CW7: 18.48 | CX7: 21.33 | CY7: 21.33 | CZ7: 29.05 | DA7: 41.45 | DB7: 42.7 | DC7: 41.52 | DD7: 37.2 | DE7: 28.23 | DF7: 28.84 | DG7: 25.59 | DH7: 21.33 | DI7: 21.12 | DJ7: 21.73 | DK7: 21.73 | DL7: 19.7 | DM7: 19.91 | DN7: 20.11 | DO7: 20.11 | DP7: 24.58 | DQ7: 27.02 | DR7: 21.33 | DS7: 22.95 | DT7: 17.47 | DU7: 18.89 | DV7: 15.23 | DW7: 17.47 | DX7: 17.27 | DY7: 17.8
B8: 16.19 | C8: 17.88 | D8: 19.91 | E8: 18.89 | F8: 17.47 | G8: 18.08 | H8: 18.08 | I8: 18.28 | J8: 23.16 | K8: 53.62 | L8: 63.53 | M8: 30.67 | N8: 19.3 | O8: 18.89 | P8: 17.47 | Q8: 21.33 | R8: 22.56 | S8: 21.73 | T8: 23.97 | U8: 27.22 | V8: 29.05 | W8: 37.81 | X8: 50.28 | Y8: 49.47 | Z8: 50.05 | AA8: 48.78 | AB8: 39.67 | AC8: 37.39 | AD8: 33.92 | AE8: 25.59 | AF8: 22.75 | AG8: 22.14 | AH8: 20.92 | AI8: 20.31 | AJ8: 19.91 | AK8: 18.08 | AL8: 19.91 | AM8: 17.06 | AN8: 19.91 | AO8: 24.38 | AP8: 33.34 | AQ8: 63.41 | AR8: 69.53 | AS8: 41.3 | AT8: 27.02 | AU8: 26.61 | AV8: 24.17 | AW8: 21.53 | AX8: 20.11 | AY8: 22.34 | AZ8: 19.3 | BA8: 20.31 | BB8: 20.11 | BC8: 21.73 | BD8: 18.69 | BE8: 20.11 | BF8: 20.31 | BG8: 19.3 | BH8: 19.5 | BI8: 19.91 | BJ8: 20.52 | BK8: 19.3 | BL8: 18.08 | BM8: 18.89 | BN8: 19.09 | BO8: 18.28 | BP8: 16.45 | BQ8: 17.06 | BR8: 14.83 | BS8: 16.66 | BT8: 18.28 | BU8: 20.72 | BV8: 47.31 | BW8: 83.91 | BX8: 132.05 | BY8: 115.34 | BZ8: 82.25 | CA8: 39.3 | CB8: 23.56 | CC8: 20.72 | CD8: 21.53 | CE8: 20.92 | CF8: 21.73 | CG8: 20.52 | CH8: 18.28 | CI8: 16.86 | CJ8: 15.84 | CK8: 16.05 | CL8: 17.06 | CM8: 16.86 | CN8: 17.67 | CO8: 16.66 | CP8: 18.69 | CQ8: 18.89 | CR8: 16.66 | CS8: 18.28 | CT8: 18.48 | CU8: 18.69 | CV8: 16.86 | CW8: 18.28 | CX8: 21.12 | CY8: 24.38 | CZ8: 33.11 | DA8: 34.33 | DB8: 30.67 | DC8: 24.58 | DD8: 24.58 | DE8: 24.78 | DF8: 26.22 | DG8: 24.17 | DH8: 21.73 | DI8: 21.73 | DJ8: 21.12 | DK8: 21.53 | DL8: 20.72 | DM8: 19.91 | DN8: 18.69 | DO8: 19.09 | DP8: 24.98 | DQ8: 26.41 | DR8: 28.86 | DS8: 20.31 | DT8: 22.34 | DU8: 20.31 | DV8: 18.28 | DW8: 18.08 | DX8: 16.45 | DY8: 16.39
B9: 17.81 | C9: 18.48 | D9: 17.47 | E9: 19.91 | F9: 19.3 | G9: 18.69 | H9: 17.67 | I9: 20.11 | J9: 31.3 | K9: 61.42 | L9: 57.67 | M9: 29.05 | N9: 20.92 | O9: 18.89 | P9: 19.91 | Q9: 23.77 | R9: 25.59 | S9: 25.19 | T9: 36.39 | U9: 46.78 | V9: 50.52 | W9: 47.81 | X9: 41.67 | Y9: 40.45 | Z9: 40.03 | AA9: 41.25 | AB9: 37.17 | AC9: 30.67 | AD9: 25.59 | AE9: 21.53 | AF9: 19.5 | AG9: 18.08 | AH9: 20.11 | AI9: 18.48 | AJ9: 18.69 | AK9: 20.72 | AL9: 20.92 | AM9: 20.11 | AN9: 20.31 | AO9: 20.72 | AP9: 25.39 | AQ9: 39.86 | AR9: 98.05 | AS9: 82.72 | AT9: 52.67 | AU9: 26.41 | AV9: 23.97 | AW9: 19.09 | AX9: 21.73 | AY9: 20.92 | AZ9: 17.88 | BA9: 19.7 | BB9: 19.5 | BC9: 16.45 | BD9: 18.48 | BE9: 18.89 | BF9: 19.3 | BG9: 20.31 | BH9: 21.12 | BI9: 18.28 | BJ9: 18.89 | BK9: 17.06 | BL9: 17.06 | BM9: 16.86 | BN9: 15.03 | BO9: 15.03 | BP9: 14.62 | BQ9: 14.83 | BR9: 16.05 | BS9: 17.67 | BT9: 21.33 | BU9: 36.64 | BV9: 77.89 | BW9: 128.23 | BX9: 118.27 | BY9: 95.38 | BZ9: 54.69 | CA9: 29.25 | CB9: 21.94 | CC9: 20.92 | CD9: 19.3 | CE9: 19.09 | CF9: 20.52 | CG9: 21.12 | CH9: 19.3 | CI9: 19.09 | CJ9: 17.06 | CK9: 17.27 | CL9: 18.69 | CM9: 18.28 | CN9: 18.08 | CO9: 18.28 | CP9: 18.28 | CQ9: 15.03 | CR9: 15.64 | CS9: 17.67 | CT9: 19.3 | CU9: 18.08 | CV9: 17.88 | CW9: 19.91 | CX9: 21.53 | CY9: 29.05 | CZ9: 29.25 | DA9: 27.02 | DB9: 20.92 | DC9: 19.09 | DD9: 19.7 | DE9: 21.12 | DF9: 20.11 | DG9: 19.7 | DH9: 21.53 | DI9: 19.7 | DJ9: 22.14 | DK9: 20.72 | DL9: 20.92 | DM9: 19.91 | DN9: 21.33 | DO9: 22.14 | DP9: 23.56 | DQ9: 27.83 | DR9: 26.81 | DS9: 24.58 | DT9: 19.09 | DU9: 18.89 | DV9: 19.3 | DW9: 17.47 | DX9: 17.27 | DY9: 18.42
A10: 2 | B10: 17.81 | C10: 19.7 | D10: 16.25 | E10: 20.52 | F10: 21.73 | G10: 18.48 | H10: 19.5 | I10: 24.38 | J10: 42.92 | K10: 49.84 | L10: 66.19 | M10: 36.17 | N10: 22.34 | O10: 22.95 | P10: 22.14 | Q10: 25.59 | R10: 31.5 | S10: 50.94 | T10: 65.38 | U10: 59.12 | V10: 48.83 | W10: 42.75 | X10: 38.59 | Y10: 35.55 | Z10: 31.28 | AA10: 31.08 | AB10: 27.42 | AC10: 24.78 | AD10: 22.95 | AE10: 19.3 | AF10: 17.47 | AG10: 18.28 | AH10: 15.64 | AI10: 17.27 | AJ10: 16.86 | AK10: 18.28 | AL10: 20.72 | AM10: 21.94 | AN10: 21.12 | AO10: 20.92 | AP10: 23.77 | AQ10: 34.75 | AR10: 118.47 | AS10: 164.17 | AT10: 72.78 | AU10: 24.98 | AV10: 23.16 | AW10: 18.08 | AX10: 18.08 | AY10: 19.5 | AZ10: 19.5 | BA10: 16.86 | BB10: 17.06 | BC10: 18.48 | BD10: 18.08 | BE10: 18.69 | BF10: 22.55 | BG10: 20.92 | BH10: 20.72 | BI10: 17.27 | BJ10: 17.67 | BK10: 19.09 | BL10: 19.91 | BM10: 14.42 | BN10: 15.84 | BO10: 13.81 | BP10: 13.81 | BQ10: 14.83 | BR10: 19.3 | BS10: 20.92 | BT10: 44.23 | BU10: 89.5 | BV10: 134.72 | BW10: 148.16 | BX10: 122.61 | BY10: 91.34 | BZ10: 47.47 | CA10: 24.58 | CB10: 21.94 | CC10: 22.14 | CD10: 20.11 | CE10: 19.09 | CF10: 18.69 | CG10: 18.48 | CH10: 18.08 | CI10: 17.88 | CJ10: 20.92 | CK10: 20.31 | CL10: 19.7 | CM10: 18.69 | CN10: 19.5 | CO10: 18.89 | CP10: 18.08 | CQ10: 17.67 | CR10: 16.66 | CS10: 17.67 | CT10: 18.08 | CU10: 18.48 | CV10: 16.05 | CW10: 18.28 | CX10: 28.64 | CY10: 27.64 | CZ10: 26 | DA10: 23.56 | DB10: 18.09 | DC10: 17.08 | DD10: 17.06 | DE10: 19.91 | DF10: 16.25 | DG10: 15.44 | DH10: 17.88 | DI10: 19.5 | DJ10: 19.91 | DK10: 20.11 | DL10: 19.3 | DM10: 19.3 | DN10: 24 | DO10: 19.3 | DP10: 21.12 | DQ10: 26.2 | DR10: 25.59 | DS10: 21.53 | DT10: 19.5 | DU10: 21.33 | DV10: 19.91 | DW10: 19.09 | DX10: 18.48 | DY10: 17.41
B11: 17.58 | C11: 16.45 | D11: 16.86 | E11: 18.69 | F11: 20.52 | G11: 18.08 | H11: 20.52 | I11: 33.95 | J11: 50.66 | K11: 53.33 | L11: 63.92 | M11: 43.92 | N11: 40.05 | O11: 32.73 | P11: 32.91 | Q11: 46.84 | R11: 64.92 | S11: 64.34 | T11: 42.73 | U11: 30.88 | V11: 29.66 | W11: 28.84 | X11: 26.41 | Y11: 28.64 | Z11: 28.84 | AA11: 23.77 | AB11: 22.75 | AC11: 22.75 | AD11: 19.7 | AE11: 19.5 | AF11: 20.72 | AG11: 16.45 | AH11: 16.66 | AI11: 15.44 | AJ11: 16.05 | AK11: 18.28 | AL11: 22.75 | AM11: 25.19 | AN11: 24.38 | AO11: 20.11 | AP11: 23.36 | AQ11: 49.64 | AR11: 122.16 | AS11: 115.75 | AT11: 45.03 | AU11: 23.16 | AV11: 19.91 | AW11: 19.3 | AX11: 17.88 | AY11: 20.72 | AZ11: 19.7 | BA11: 19.7 | BB11: 19.91 | BC11: 19.91 | BD11: 20.11 | BE11: 20.11 | BF11: 22.75 | BG11: 19.3 | BH11: 18.08 | BI11: 17.06 | BJ11: 18.69 | BK11: 17.27 | BL11: 16.05 | BM11: 15.44 | BN11: 15.23 | BO11: 14.42 | BP11: 16.05 | BQ11: 15.64 | BR11: 28.7 | BS11: 66.12 | BT11: 93.48 | BU11: 153.61 | BV11: 159.58 | BW11: 140.56 | BX11: 105.34 | BY11: 64.34 | BZ11: 37.2 | CA11: 23.97 | CB11: 21.12 | CC11: 20.52 | CD11: 17.27 | CE11: 21.73 | CF11: 22.95 | CG11: 17.88 | CH11: 17.47 | CI11: 19.5 | CJ11: 21.73 | CK11: 21.94 | CL11: 23.77 | CM11: 21.53 | CN11: 20.52 | CO11: 17.88 | CP11: 17.06 | CQ11: 17.06 | CR11: 16.86 | CS11: 20.52 | CT11: 18.48 | CU11: 19.09 | CV11: 19.09 | CW11: 24.58 | CX11: 29.05 | CY11: 26.62 | CZ11: 23.36 | DA11: 18.28 | DB11: 18.89 | DC11: 14.02 | DD11: 15.23 | DE11: 17.06 | DF11: 15.64 | DG11: 15.44 | DH11: 16.66 | DI11: 18.69 | DJ11: 17.47 | DK11: 16.66 | DL11: 18.08 | DM11: 19.5 | DN11: 17.67 | DO11: 18.69 | DP11: 20.31 | DQ11: 26.41 | DR11: 26 | DS11: 20.11 | DT11: 18.69 | DU11: 17.88 | DV11: 20.11 | DW11: 19.3 | DX11: 16.45 | DY11: 17
B12: 18.41 | C12: 19.7 | D12: 17.06 | E12: 18.08 | F12: 20.31 | G12: 18.28 | H12: 22.14 | I12: 42.09 | J12: 56.64 | K12: 60.34 | L12: 68.5 | M12: 50.89 | N12: 52.11 | O12: 49.42 | P12: 51.7 | Q12: 60.39 | R12: 42.75 | S12: 31.89 | T12: 27.03 | U12: 26 | V12: 29.86 | W12: 28.84 | X12: 26.81 | Y12: 23.36 | Z12: 22.95 | AA12: 20.92 | AB12: 21.12 | AC12: 19.91 | AD12: 19.91 | AE12: 19.3 | AF12: 19.3 | AG12: 20.52 | AH12: 18.69 | AI12: 19.7 | AJ12: 19.3 | AK12: 21.33 | AL12: 22.14 | AM12: 31.58 | AN12: 24.22 | AO12: 21.73 | AP12: 26.41 | AQ12: 72.92 | AR12: 111.81 | AS12: 101.59 | AT12: 38.3 | AU12: 22.75 | AV12: 20.11 | AW12: 22.14 | AX12: 20.92 | AY12: 20.53 | AZ12: 19.3 | BA12: 18.28 | BB12: 20.31 | BC12: 19.09 | BD12: 19.5 | BE12: 17.47 | BF12: 22.55 | BG12: 23.56 | BH12: 18.28 | BI12: 15.44 | BJ12: 17.88 | BK12: 16.25 | BL12: 16.05 | BM12: 14.42 | BN12: 16.45 | BO12: 15.84 | BP12: 19.5 | BQ12: 33.62 | BR12: 74.14 | BS12: 90.33 | BT12: 120.72 | BU12: 161.95 | BV12: 148.64 | BW12: 139.89 | BX12: 95.75 | BY12: 53.59 | BZ12: 39.66 | CA12: 25.59 | CB12: 20.31 | CC12: 18.28 | CD12: 17.67 | CE12: 19.91 | CF12: 19.7 | CG12: 20.92 | CH12: 19.5 | CI12: 20.11 | CJ12: 18.28 | CK12: 21.53 | CL12: 23.16 | CM12: 24.58 | CN12: 19.91 | CO12: 20.31 | CP12: 17.47 | CQ12: 18.08 | CR12: 17.67 | CS12: 21.12 | CT12: 31.8 | CU12: 20.11 | CV12: 24.78 | CW12: 28.23 | CX12: 31.28 | CY12: 22.75 | CZ12: 19.3 | DA12: 16.66 | DB12: 16.25 | DC12: 14.02 | DD12: 16.25 | DE12: 17.06 | DF12: 14.02 | DG12: 14.22 | DH12: 15.64 | DI12: 17.47 | DJ12: 16.05 | DK12: 16.05 | DL12: 18.89 | DM12: 19.3 | DN12: 17.88 | DO12: 19.91 | DP12: 21.53 | DQ12: 24.98 | DR12: 21.12 | DS12: 19.5 | DT12: 20.72 | DU12: 18.69 | DV12: 17.06 | DW12: 16.05 | DX12: 14.42 | DY12: 16.39
B13: 17.81 | C13: 17.47 | D13: 17.47 | E13: 20.31 | F13: 21.73 | G13: 19.5 | H13: 19.91 | I13: 48.41 | J13: 52.73 | K13: 58.94 | L13: 58.27 | M13: 56.69 | N13: 55.23 | O13: 52.53 | P13: 54.16 | Q13: 34.16 | R13: 24.17 | S13: 26.81 | T13: 27.42 | U13: 24.98 | V13: 26 | W13: 26.41 | X13: 20.72 | Y13: 26.61 | Z13: 21.53 | AA13: 17.88 | AB13: 19.5 | AC13: 18.48 | AD13: 19.3 | AE13: 17.88 | AF13: 21.12 | AG13: 22.95 | AH13: 23.36 | AI13: 25.86 | AJ13: 25.59 | AK13: 26.41 | AL13: 23.77 | AM13: 22.34 | AN13: 20.72 | AO13: 23.36 | AP13: 35.62 | AQ13: 111.58 | AR13: 111.58 | AS13: 81.03 | AT13: 26.2 | AU13: 22.34 | AV13: 17.06 | AW13: 20.31 | AX13: 20.72 | AY13: 18.69 | AZ13: 20.92 | BA13: 20.31 | BB13: 19.5 | BC13: 17.67 | BD13: 28.73 | BE13: 20.72 | BF13: 20.72 | BG13: 21.12 | BH13: 21.12 | BI13: 17.47 | BJ13: 16.66 | BK13: 16.86 | BL13: 15.03 | BM13: 15.03 | BN13: 15.64 | BO13: 17.88 | BP13: 26.86 | BQ13: 65.44 | BR13: 72 | BS13: 87.59 | BT13: 135.42 | BU13: 159.55 | BV13: 141.42 | BW13: 101.39 | BX13: 66.61 | BY13: 47.14 | BZ13: 40.02 | CA13: 36.19 | CB13: 23.36 | CC13: 19.91 | CD13: 20.72 | CE13: 21.12 | CF13: 21.33 | CG13: 22.75 | CH13: 21.73 | CI13: 19.7 | CJ13: 20.52 | CK13: 23.56 | CL13: 23.97 | CM13: 27.44 | CN13: 34.27 | CO13: 19.3 | CP13: 17.88 | CQ13: 16.45 | CR13: 19.31 | CS13: 19.3 | CT13: 19.7 | CU13: 19.91 | CV13: 27.22 | CW13: 27.22 | CX13: 23.56 | CY13: 18.48 | CZ13: 16.05 | DA13: 17.88 | DB13: 15.23 | DC13: 14.83 | DD13: 14.62 | DE13: 16.66 | DF13: 15.84 | DG13: 15.23 | DH13: 16.66 | DI13: 17.27 | DJ13: 16.25 | DK13: 17.47 | DL13: 17.67 | DM13: 18.48 | DN13: 19.3 | DO13: 19.5 | DP13: 21.53 | DQ13: 20.72 | DR13: 17.88 | DS13: 19.91 | DT13: 19.7 | DU13: 18.69 | DV13: 16.45 | DW13: 14.62 | DX13: 14.62 | DY13: 14.75
A14: 3 | B14: 18.42 | C14: 20.52 | D14: 20.72 | E14: 22.75 | F14: 20.31 | G14: 19.09 | H14: 21.33 | I14: 44.59 | J14: 46.81 | K14: 55.17 | L14: 56.5 | M14: 49.45 | N14: 50.94 | O14: 49.27 | P14: 51.81 | Q14: 21.94 | R14: 22.34 | S14: 25.39 | T14: 24.98 | U14: 22.34 | V14: 24.17 | W14: 21.73 | X14: 20.92 | Y14: 21.33 | Z14: 20.31 | AA14: 21.12 | AB14: 23.98 | AC14: 20.92 | AD14: 19.5 | AE14: 21.33 | AF14: 22.34 | AG14: 23.77 | AH14: 25.59 | AI14: 23.16 | AJ14: 23.56 | AK14: 24.98 | AL14: 21.12 | AM14: 20.31 | AN14: 19.3 | AO14: 23.16 | AP14: 63.67 | AQ14: 144.52 | AR14: 109.42 | AS14: 43.42 | AT14: 19.91 | AU14: 16.86 | AV14: 19.09 | AW14: 16.25 | AX14: 19.3 | AY14: 17.88 | AZ14: 16.66 | BA14: 20.31 | BB14: 17.27 | BC14: 20.31 | BD14: 20.31 | BE14: 20.92 | BF14: 19.7 | BG14: 20.31 | BH14: 19.5 | BI14: 21.73 | BJ14: 21.73 | BK14: 17.67 | BL14: 17.88 | BM14: 18.69 | BN14: 17.27 | BO14: 19.7 | BP14: 54.12 | BQ14: 60.03 | BR14: 67.44 | BS14: 99.3 | BT14: 157.25 | BU14: 152.14 | BV14: 126.81 | BW14: 54.72 | BX14: 36.22 | BY14: 41.25 | BZ14: 35.55 | CA14: 36.97 | CB14: 32.7 | CC14: 28.44 | CD14: 28.45 | CE14: 26 | CF14: 28.03 | CG14: 27.42 | CH14: 25.59 | CI14: 21.94 | CJ14: 23.36 | CK14: 23.36 | CL14: 27.02 | CM14: 25.59 | CN14: 21.73 | CO14: 19.5 | CP14: 19.31 | CQ14: 16.86 | CR14: 16.86 | CS14: 17.47 | CT14: 23.36 | CU14: 26 | CV14: 29.25 | CW14: 24.58 | CX14: 18.48 | CY14: 17.88 | CZ14: 15.64 | DA14: 15.44 | DB14: 17.88 | DC14: 15.23 | DD14: 16.45 | DE14: 15.64 | DF14: 16.25 | DG14: 15.44 | DH14: 17.27 | DI14: 17.67 | DJ14: 17.27 | DK14: 18.69 | DL14: 17.67 | DM14: 17.88 | DN14: 22.55 | DO14: 18.69 | DP14: 21.12 | DQ14: 18.28 | DR14: 16.86 | DS14: 17.67 | DT14: 17.67 | DU14: 16.45 | DV14: 16.05 | DW14: 14.83 | DX14: 14.22 | DY14: 14.36
B15: 19.44 | C15: 19.3 | D15: 20.11 | E15: 21.33 | F15: 19.5 | G15: 21.12 | H15: 20.31 | I15: 34.19 | J15: 60.97 | K15: 66.41 | L15: 55.64 | M15: 52.31 | N15: 49.02 | O15: 47 | P15: 28.88 | Q15: 21.73 | R15: 21.94 | S15: 25.81 | T15: 21.33 | U15: 20.52 | V15: 19.91 | W15: 19.09 | X15: 18.08 | Y15: 19.5 | Z15: 21.53 | AA15: 22.55 | AB15: 20.52 | AC15: 20.31 | AD15: 21.33 | AE15: 21.73 | AF15: 23.56 | AG15: 21.94 | AH15: 20.72 | AI15: 22.14 | AJ15: 21.33 | AK15: 23.16 | AL15: 19.09 | AM15: 21.94 | AN15: 22.75 | AO15: 28.86 | AP15: 99.75 | AQ15: 182.25 | AR15: 116.28 | AS15: 25.39 | AT15: 20.52 | AU15: 17.47 | AV15: 17.27 | AW15: 17.47 | AX15: 17.88 | AY15: 17.27 | AZ15: 19.7 | BA15: 17.47 | BB15: 18.08 | BC15: 18.69 | BD15: 20.11 | BE15: 21.73 | BF15: 21.53 | BG15: 26.05 | BH15: 30.08 | BI15: 21.33 | BJ15: 22.55 | BK15: 19.91 | BL15: 19.7 | BM15: 41.78 | BN15: 76.73 | BO15: 60.19 | BP15: 65.39 | BQ15: 71.2 | BR15: 93.25 | BS15: 132.2 | BT15: 156.38 | BU15: 141.14 | BV15: 98.72 | BW15: 35.03 | BX15: 23.77 | BY15: 32.09 | BZ15: 35.55 | CA15: 38.19 | CB15: 41.69 | CC15: 39.03 | CD15: 32.7 | CE15: 31.08 | CF15: 25.39 | CG15: 24.58 | CH15: 23.77 | CI15: 22.95 | CJ15: 25.19 | CK15: 22.55 | CL15: 26.61 | CM15: 23.77 | CN15: 21.73 | CO15: 18.48 | CP15: 19.3 | CQ15: 18.28 | CR15: 16.25 | CS15: 17.06 | CT15: 24.58 | CU15: 33.92 | CV15: 27.62 | CW15: 21.73 | CX15: 20.11 | CY15: 15.84 | CZ15: 21.94 | DA15: 24.17 | DB15: 22.34 | DC15: 20.52 | DD15: 17.27 | DE15: 16.66 | DF15: 14.83 | DG15: 15.44 | DH15: 17.88 | DI15: 17.47 | DJ15: 16.05 | DK15: 17.47 | DL15: 16.86 | DM15: 17.67 | DN15: 16.45 | DO15: 18.08 | DP15: 16.66 | DQ15: 16.25 | DR15: 17.47 | DS15: 19.72 | DT15: 16.86 | DU15: 16.45 | DV15: 15.84 | DW15: 14.22 | DX15: 14.02 | DY15: 14.97
B16: 20.05 | C16: 18.69 | D16: 17.88 | E16: 17.67 | F16: 16.66 | G16: 18.48 | H16: 19.5 | I16: 24.19 | J16: 52.52 | K16: 61.66 | L16: 60.97 | M16: 57.05 | N16: 50.67 | O16: 35.36 | P16: 22.55 | Q16: 21.53 | R16: 17.47 | S16: 20.31 | T16: 19.91 | U16: 19.09 | V16: 20.31 | W16: 20.92 | X16: 16.25 | Y16: 19.92 | Z16: 18.69 | AA16: 21.94 | AB16: 22.14 | AC16: 21.12 | AD16: 18.89 | AE16: 21.73 | AF16: 23.56 | AG16: 20.92 | AH16: 20.11 | AI16: 22.55 | AJ16: 21.53 | AK16: 21.95 | AL16: 20.72 | AM16: 21.95 | AN16: 23.36 | AO16: 30.47 | AP16: 137.17 | AQ16: 181.39 | AR16: 68.42 | AS16: 23.16 | AT16: 18.69 | AU16: 17.06 | AV16: 18.69 | AW16: 18.28 | AX16: 17.06 | AY16: 17.06 | AZ16: 17.67 | BA16: 20.92 | BB16: 21.12 | BC16: 21.53 | BD16: 21.73 | BE16: 19.3 | BF16: 21.12 | BG16: 18.08 | BH16: 20.31 | BI16: 20.52 | BJ16: 21.33 | BK16: 20.11 | BL16: 22.55 | BM16: 87.48 | BN16: 90.94 | BO16: 137.84 | BP16: 110.7 | BQ16: 80.39 | BR16: 112.61 | BS16: 152.84 | BT16: 170.64 | BU16: 119.34 | BV16: 41.86 | BW16: 26.81 | BX16: 21.33 | BY16: 19.5 | BZ16: 26.41 | CA16: 31.89 | CB16: 35.56 | CC16: 33.11 | CD16: 27.22 | CE16: 23.16 | CF16: 34.84 | CG16: 21.53 | CH16: 22.14 | CI16: 24.58 | CJ16: 27.03 | CK16: 26.61 | CL16: 27.22 | CM16: 23.56 | CN16: 19.7 | CO16: 17.67 | CP16: 16.05 | CQ16: 19.09 | CR16: 15.64 | CS16: 18.08 | CT16: 27.84 | CU16: 27.42 | CV16: 25.59 | CW16: 23.36 | CX16: 22.95 | CY16: 21.53 | CZ16: 20.72 | DA16: 23.36 | DB16: 23.36 | DC16: 21.12 | DD16: 19.7 | DE16: 16.86 | DF16: 15.23 | DG16: 15.84 | DH16: 14.83 | DI16: 17.27 | DJ16: 17.06 | DK16: 19.3 | DL16: 21.12 | DM16: 19.3 | DN16: 19.7 | DO16: 17.67 | DP16: 17.27 | DQ16: 17.47 | DR16: 18.69 | DS16: 19.09 | DT16: 19.3 | DU16: 16.66 | DV16: 13.81 | DW16: 13.61 | DX16: 14.42 | DY16: 15.38
B17: 20.44 | C17: 16.88 | D17: 18.89 | E17: 18.69 | F17: 18.08 | G17: 17.67 | H17: 17.47 | I17: 19.5 | J17: 45.62 | K17: 59.5 | L17: 78.03 | M17: 72.66 | N17: 59.09 | O17: 33.14 | P17: 20.72 | Q17: 20.31 | R17: 21.12 | S17: 18.69 | T17: 20.72 | U17: 20.11 | V17: 21.73 | W17: 20.72 | X17: 19.09 | Y17: 16.25 | Z17: 15.64 | AA17: 17.88 | AB17: 18.69 | AC17: 19.3 | AD17: 18.89 | AE17: 16.66 | AF17: 19.91 | AG17: 19.09 | AH17: 20.72 | AI17: 20.11 | AJ17: 19.09 | AK17: 20.72 | AL17: 21.73 | AM17: 21.53 | AN17: 23.16 | AO17: 48.8 | AP17: 193.14 | AQ17: 176.8 | AR17: 42.22 | AS17: 22.14 | AT17: 21.12 | AU17: 18.89 | AV17: 18.48 | AW17: 19.5 | AX17: 20.31 | AY17: 17.67 | AZ17: 19.3 | BA17: 21.94 | BB17: 26.2 | BC17: 38.62 | BD17: 34.55 | BE17: 21.53 | BF17: 20.72 | BG17: 18.69 | BH17: 20.11 | BI17: 21.53 | BJ17: 19.5 | BK17: 20.31 | BL17: 24.38 | BM17: 54.3 | BN17: 149.34 | BO17: 132.81 | BP17: 149.75 | BQ17: 121.7 | BR17: 136.58 | BS17: 177.92 | BT17: 154.28 | BU17: 37.31 | BV17: 22.55 | BW17: 21.94 | BX17: 18.69 | BY17: 20.11 | BZ17: 20.92 | CA17: 23.77 | CB17: 25.8 | CC17: 23.77 | CD17: 24.17 | CE17: 26.41 | CF17: 25.8 | CG17: 23.97 | CH17: 23.77 | CI17: 23.77 | CJ17: 25.8 | CK17: 26 | CL17: 22.55 | CM17: 22.14 | CN17: 17.88 | CO17: 16.86 | CP17: 16.86 | CQ17: 16.25 | CR17: 18.69 | CS17: 23.16 | CT17: 29.47 | CU17: 25.8 | CV17: 22.75 | CW17: 24.78 | CX17: 20.92 | CY17: 18.69 | CZ17: 17.88 | DA17: 17.88 | DB17: 20.31 | DC17: 25.81 | DD17: 25.8 | DE17: 19.09 | DF17: 20.72 | DG17: 18.28 | DH17: 18.08 | DI17: 17.88 | DJ17: 17.47 | DK17: 19.7 | DL17: 17.67 | DM17: 19.09 | DN17: 18.28 | DO17: 19.09 | DP17: 19.5 | DQ17: 16.25 | DR17: 16.86 | DS17: 16.25 | DT17: 16.25 | DU17: 15.64 | DV17: 14.02 | DW17: 13.41 | DX17: 15.23 | DY17: 15.38
A18: 4 | B18: 18.83 | C18: 16.86 | D18: 19.7 | E18: 18.28 | F18: 18.28 | G18: 16.05 | H18: 16.25 | I18: 19.09 | J18: 31.3 | K18: 71.77 | L18: 102.45 | M18: 100.5 | N18: 59.95 | O18: 24.59 | P18: 21.33 | Q18: 20.11 | R18: 20.52 | S18: 19.7 | T18: 20.72 | U18: 25 | V18: 26.62 | W18: 22.75 | X18: 18.28 | Y18: 17.47 | Z18: 17.88 | AA18: 18.28 | AB18: 19.91 | AC18: 18.89 | AD18: 17.88 | AE18: 18.89 | AF18: 18.89 | AG18: 17.88 | AH18: 20.92 | AI18: 21.73 | AJ18: 20.92 | AK18: 19.09 | AL18: 21.12 | AM18: 22.34 | AN18: 24.58 | AO18: 93.77 | AP18: 199.95 | AQ18: 101.36 | AR18: 27.62 | AS18: 21.53 | AT18: 20.52 | AU18: 18.08 | AV18: 20.72 | AW18: 21.53 | AX18: 20.92 | AY18: 21.53 | AZ18: 19.09 | BA18: 21.34 | BB18: 26.2 | BC18: 27.02 | BD18: 21.12 | BE18: 20.31 | BF18: 21.53 | BG18: 22.34 | BH18: 20.72 | BI18: 21.53 | BJ18: 19.91 | BK18: 21.12 | BL18: 21.33 | BM18: 29.27 | BN18: 103.31 | BO18: 159.53 | BP18: 127 | BQ18: 147.64 | BR18: 168.91 | BS18: 159.11 | BT18: 50.92 | BU18: 21.33 | BV18: 18.89 | BW18: 18.69 | BX18: 15.23 | BY18: 19.09 | BZ18: 22.14 | CA18: 23.16 | CB18: 22.95 | CC18: 22.75 | CD18: 21.94 | CE18: 25.19 | CF18: 26.62 | CG18: 24.58 | CH18: 25.19 | CI18: 25.81 | CJ18: 25.39 | CK18: 19.7 | CL18: 18.69 | CM18: 19.5 | CN18: 17.27 | CO18: 18.48 | CP18: 18.28 | CQ18: 17.67 | CR18: 19.5 | CS18: 27.42 | CT18: 26.81 | CU18: 23.36 | CV18: 20.52 | CW18: 19.09 | CX18: 19.09 | CY18: 16.05 | CZ18: 14.42 | DA18: 13.81 | DB18: 14.22 | DC18: 23.8 | DD18: 16.45 | DE18: 19.09 | DF18: 19.3 | DG18: 19.91 | DH18: 19.3 | DI18: 18.48 | DJ18: 20.11 | DK18: 16.25 | DL18: 16.45 | DM18: 18.08 | DN18: 18.08 | DO18: 17.88 | DP18: 23.58 | DQ18: 16.45 | DR18: 17.67 | DS18: 16.66 | DT18: 16.45 | DU18: 16.05 | DV18: 15.64 | DW18: 15.86 | DX18: 16.25 | DY18: 15.36
B19: 17.2 | C19: 18.69 | D19: 18.48 | E19: 19.91 | F19: 17.88 | G19: 16.25 | H19: 16.86 | I19: 16.45 | J19: 28.66 | K19: 72.44 | L19: 123.23 | M19: 126.19 | N19: 45.39 | O19: 21.33 | P19: 20.92 | Q19: 18.48 | R19: 20.11 | S19: 21.33 | T19: 28.03 | U19: 24.58 | V19: 22.14 | W19: 21.94 | X19: 23.36 | Y19: 18.28 | Z19: 19.7 | AA19: 18.69 | AB19: 15.64 | AC19: 15.03 | AD19: 16.05 | AE19: 19.09 | AF19: 21.33 | AG19: 18.69 | AH19: 21.73 | AI19: 21.12 | AJ19: 21.12 | AK19: 20.52 | AL19: 20.92 | AM19: 20.52 | AN19: 47.81 | AO19: 161.34 | AP19: 126.67 | AQ19: 35.62 | AR19: 20.52 | AS19: 20.72 | AT19: 21.12 | AU19: 22.55 | AV19: 21.33 | AW19: 23.77 | AX19: 23.16 | AY19: 23.77 | AZ19: 23.77 | BA19: 20.72 | BB19: 20.72 | BC19: 18.28 | BD19: 18.28 | BE19: 19.09 | BF19: 21.53 | BG19: 21.12 | BH19: 20.31 | BI19: 20.72 | BJ19: 19.7 | BK19: 22.75 | BL19: 26.2 | BM19: 53.92 | BN19: 86.36 | BO19: 158.45 | BP19: 150.2 | BQ19: 166.14 | BR19: 170.84 | BS19: 64.75 | BT19: 22.14 | BU19: 17.27 | BV19: 16.66 | BW19: 15.84 | BX19: 17.27 | BY19: 20.52 | BZ19: 21.73 | CA19: 22.14 | CB19: 24.17 | CC19: 24.58 | CD19: 20.52 | CE19: 23.36 | CF19: 24.98 | CG19: 26.2 | CH19: 25.59 | CI19: 25.59 | CJ19: 21.12 | CK19: 17.47 | CL19: 17.47 | CM19: 17.06 | CN19: 17.67 | CO19: 16.25 | CP19: 16.86 | CQ19: 21.33 | CR19: 27.83 | CS19: 24.98 | CT19: 26.41 | CU19: 24.98 | CV19: 18.48 | CW19: 18.3 | CX19: 16.25 | CY19: 16.05 | CZ19: 14.83 | DA19: 15.64 | DB19: 15.03 | DC19: 15.64 | DD19: 15.84 | DE19: 21.94 | DF19: 18.69 | DG19: 16.66 | DH19: 17.88 | DI19: 18.48 | DJ19: 18.69 | DK19: 17.67 | DL19: 17.47 | DM19: 18.48 | DN19: 18.69 | DO19: 18.08 | DP19: 16.66 | DQ19: 15.44 | DR19: 17.67 | DS19: 18.28 | DT19: 16.45 | DU19: 18.28 | DV19: 14.83 | DW19: 15.44 | DX19: 15.03 | DY19: 16.39
B20: 18.42 | C20: 20.72 | D20: 20.92 | E20: 19.3 | F20: 17.88 | G20: 16.45 | H20: 15.64 | I20: 15.44 | J20: 20.52 | K20: 72.92 | L20: 139.52 | M20: 133.69 | N20: 36.62 | O20: 21.94 | P20: 18.08 | Q20: 18.89 | R20: 19.5 | S20: 21.12 | T20: 26.41 | U20: 26.2 | V20: 22.36 | W20: 27.28 | X20: 26.45 | Y20: 18.69 | Z20: 17.47 | AA20: 17.06 | AB20: 15.23 | AC20: 18.48 | AD20: 18.28 | AE20: 17.88 | AF20: 18.89 | AG20: 19.5 | AH20: 22.75 | AI20: 22.95 | AJ20: 22.95 | AK20: 20.72 | AL20: 22.14 | AM20: 23.56 | AN20: 60.88 | AO20: 68.19 | AP20: 28.03 | AQ20: 20.72 | AR20: 20.11 | AS20: 20.11 | AT20: 18.48 | AU20: 21.12 | AV20: 20.92 | AW20: 25.39 | AX20: 25.19 | AY20: 25.19 | AZ20: 22.75 | BA20: 18.28 | BB20: 17.88 | BC20: 18.69 | BD20: 16.86 | BE20: 17.47 | BF20: 23.56 | BG20: 18.08 | BH20: 18.89 | BI20: 22.34 | BJ20: 22.75 | BK20: 29.89 | BL20: 49.78 | BM20: 84.12 | BN20: 89.52 | BO20: 154.98 | BP20: 180.64 | BQ20: 182.25 | BR20: 125.56 | BS20: 29.47 | BT20: 18.69 | BU20: 17.06 | BV20: 16.86 | BW20: 17.27 | BX20: 17.88 | BY20: 19.91 | BZ20: 22.14 | CA20: 20.52 | CB20: 22.14 | CC20: 22.34 | CD20: 21.33 | CE20: 20.31 | CF20: 21.12 | CG20: 22.34 | CH20: 23.77 | CI20: 20.31 | CJ20: 19.09 | CK20: 16.25 | CL20: 21.33 | CM20: 18.48 | CN20: 19.5 | CO20: 18.08 | CP20: 19.3 | CQ20: 28.03 | CR20: 27.62 | CS20: 24.38 | CT20: 20.11 | CU20: 20.31 | CV20: 19.91 | CW20: 15.84 | CX20: 16.25 | CY20: 14.42 | CZ20: 21.73 | DA20: 15.64 | DB20: 16.05 | DC20: 15.44 | DD20: 18.08 | DE20: 16.45 | DF20: 16.66 | DG20: 15.64 | DH20: 16.05 | DI20: 17.06 | DJ20: 21.94 | DK20: 19.3 | DL20: 19.7 | DM20: 19.09 | DN20: 19.09 | DO20: 18.08 | DP20: 18.28 | DQ20: 17.47 | DR20: 18.89 | DS20: 18.69 | DT20: 18.08 | DU20: 18.48 | DV20: 18.89 | DW20: 16.45 | DX20: 16.45 | DY20: 18.02
B21: 19.03 | C21: 19.3 | D21: 19.09 | E21: 20.72 | F21: 20.72 | G21: 18.28 | H21: 16.66 | I21: 17.06 | J21: 18.48 | K21: 48.12 | L21: 141.56 | M21: 142.86 | N21: 35.42 | O21: 20.52 | P21: 18.08 | Q21: 20.31 | R21: 21.33 | S21: 21.94 | T21: 27.02 | U21: 28.25 | V21: 31.34 | W21: 21.53 | X21: 17.88 | Y21: 17.67 | Z21: 17.88 | AA21: 16.86 | AB21: 18.28 | AC21: 18.48 | AD21: 19.09 | AE21: 17.47 | AF21: 18.89 | AG21: 19.09 | AH21: 21.53 | AI21: 22.14 | AJ21: 21.53 | AK21: 21.12 | AL21: 22.34 | AM21: 22.34 | AN21: 22.75 | AO21: 21.53 | AP21: 22.95 | AQ21: 19.5 | AR21: 19.3 | AS21: 19.7 | AT21: 19.7 | AU21: 20.11 | AV21: 18.89 | AW21: 25.19 | AX21: 27.05 | AY21: 23.77 | AZ21: 19.5 | BA21: 19.3 | BB21: 18.89 | BC21: 15.03 | BD21: 15.84 | BE21: 19.09 | BF21: 19.7 | BG21: 18.48 | BH21: 21.73 | BI21: 22.14 | BJ21: 29.86 | BK21: 67.11 | BL21: 83.42 | BM21: 95.7 | BN21: 122.08 | BO21: 170.19 | BP21: 182.69 | BQ21: 158.73 | BR21: 44.44 | BS21: 22.34 | BT21: 16.86 | BU21: 16.05 | BV21: 17.27 | BW21: 16.86 | BX21: 17.27 | BY21: 21.95 | BZ21: 21.53 | CA21: 21.73 | CB21: 20.52 | CC21: 18.28 | CD21: 18.48 | CE21: 17.08 | CF21: 19.5 | CG21: 20.31 | CH21: 23.17 | CI21: 19.5 | CJ21: 18.89 | CK21: 17.27 | CL21: 17.27 | CM21: 19.5 | CN21: 19.91 | CO21: 19.09 | CP21: 25.19 | CQ21: 30.7 | CR21: 27.42 | CS21: 22.95 | CT21: 17.27 | CU21: 16.05 | CV21: 19.7 | CW21: 20.31 | CX21: 17.27 | CY21: 16.86 | CZ21: 15.84 | DA21: 15.23 | DB21: 15.64 | DC21: 16.05 | DD21: 15.64 | DE21: 16.45 | DF21: 17.06 | DG21: 15.84 | DH21: 17.06 | DI21: 20.92 | DJ21: 23.56 | DK21: 19.3 | DL21: 19.91 | DM21: 20.92 | DN21: 18.28 | DO21: 17.27 | DP21: 18.48 | DQ21: 19.09 | DR21: 18.69 | DS21: 19.7 | DT21: 20.92 | DU21: 19.09 | DV21: 18.08 | DW21: 17.67 | DX21: 17.47 | DY21: 17.81
A22: 5 | B22: 18.42 | C22: 21.33 | D22: 19.7 | E22: 20.11 | F22: 19.09 | G22: 16.45 | H22: 16.25 | I22: 15.44 | J22: 19.7 | K22: 55.8 | L22: 156.61 | M22: 155.81 | N22: 39.94 | O22: 22.95 | P22: 18.08 | Q22: 18.69 | R22: 20.31 | S22: 24.17 | T22: 23.56 | U22: 29.05 | V22: 27.62 | W22: 26.81 | X22: 19.91 | Y22: 17.88 | Z22: 18.48 | AA22: 16.86 | AB22: 17.88 | AC22: 19.91 | AD22: 18.89 | AE22: 19.09 | AF22: 19.3 | AG22: 19.7 | AH22: 18.48 | AI22: 20.31 | AJ22: 18.69 | AK22: 20.72 | AL22: 22.75 | AM22: 21.94 | AN22: 21.53 | AO22: 20.92 | AP22: 18.89 | AQ22: 21.12 | AR22: 21.94 | AS22: 20.31 | AT22: 21.12 | AU22: 16.45 | AV22: 19.5 | AW22: 21.94 | AX22: 21.94 | AY22: 21.12 | AZ22: 20.92 | BA22: 19.11 | BB22: 15.23 | BC22: 16.45 | BD22: 19.7 | BE22: 17.27 | BF22: 17.06 | BG22: 19.3 | BH22: 18.89 | BI22: 26.41 | BJ22: 60.89 | BK22: 73.06 | BL22: 78.44 | BM22: 130.12 | BN22: 168.53 | BO22: 177.34 | BP22: 189.33 | BQ22: 89.91 | BR22: 24.58 | BS22: 17.27 | BT22: 18.48 | BU22: 19.5 | BV22: 17.06 | BW22: 17.06 | BX22: 19.09 | BY22: 18.08 | BZ22: 22.34 | CA22: 20.72 | CB22: 22.75 | CC22: 19.5 | CD22: 18.69 | CE22: 19.5 | CF22: 19.09 | CG22: 18.89 | CH22: 18.89 | CI22: 18.69 | CJ22: 19.3 | CK22: 18.89 | CL22: 17.88 | CM22: 17.88 | CN22: 17.67 | CO22: 24.17 | CP22: 25.19 | CQ22: 29.05 | CR22: 23.16 | CS22: 15.64 | CT22: 17.47 | CU22: 16.05 | CV22: 17.67 | CW22: 19.3 | CX22: 17.88 | CY22: 15.03 | CZ22: 14.83 | DA22: 15.23 | DB22: 16.25 | DC22: 14.42 | DD22: 19.91 | DE22: 19.09 | DF22: 17.47 | DG22: 19.09 | DH22: 20.92 | DI22: 21.73 | DJ22: 21.12 | DK22: 18.28 | DL22: 21.73 | DM22: 20.92 | DN22: 18.89 | DO22: 17.47 | DP22: 18.48 | DQ22: 19.5 | DR22: 19.5 | DS22: 20.52 | DT22: 22.55 | DU22: 31.7 | DV22: 32.75 | DW22: 35.17 | DX22: 31.7 | DY22: 26.12
B23: 20.84 | C23: 21.73 | D23: 20.72 | E23: 20.92 | F23: 18.48 | G23: 18.08 | H23: 17.27 | I23: 15.84 | J23: 20.92 | K23: 118.5 | L23: 196.23 | M23: 206.78 | N23: 102.83 | O23: 23.78 | P23: 19.09 | Q23: 21.33 | R23: 20.92 | S23: 24.98 | T23: 25.59 | U23: 30.27 | V23: 29.45 | W23: 26 | X23: 24.78 | Y23: 21.73 | Z23: 17.88 | AA23: 16.45 | AB23: 18.89 | AC23: 21.33 | AD23: 22.14 | AE23: 22.55 | AF23: 21.53 | AG23: 18.89 | AH23: 22.55 | AI23: 24.8 | AJ23: 19.3 | AK23: 18.28 | AL23: 19.3 | AM23: 18.48 | AN23: 21.73 | AO23: 21.12 | AP23: 21.12 | AQ23: 23.56 | AR23: 19.09 | AS23: 21.33 | AT23: 20.11 | AU23: 17.06 | AV23: 20.11 | AW23: 20.11 | AX23: 19.09 | AY23: 19.5 | AZ23: 19.5 | BA23: 17.67 | BB23: 17.88 | BC23: 19.7 | BD23: 18.69 | BE23: 17.67 | BF23: 19.91 | BG23: 19.5 | BH23: 23.56 | BI23: 49.73 | BJ23: 77.42 | BK23: 77.61 | BL23: 117.41 | BM23: 171.48 | BN23: 176.55 | BO23: 158.88 | BP23: 133.02 | BQ23: 38.22 | BR23: 21.94 | BS23: 17.06 | BT23: 15.84 | BU23: 20.33 | BV23: 18.28 | BW23: 19.09 | BX23: 20.11 | BY23: 21.94 | BZ23: 21.73 | CA23: 21.12 | CB23: 20.52 | CC23: 18.69 | CD23: 17.47 | CE23: 19.7 | CF23: 19.3 | CG23: 18.69 | CH23: 18.89 | CI23: 16.66 | CJ23: 19.3 | CK23: 18.69 | CL23: 19.3 | CM23: 22.14 | CN23: 21.53 | CO23: 26.2 | CP23: 25.19 | CQ23: 25.19 | CR23: 18.69 | CS23: 19.3 | CT23: 16.86 | CU23: 17.06 | CV23: 20.31 | CW23: 19.7 | CX23: 18.08 | CY23: 15.84 | CZ23: 15.64 | DA23: 17.27 | DB23: 16.45 | DC23: 16.05 | DD23: 16.86 | DE23: 21.53 | DF23: 19.3 | DG23: 18.89 | DH23: 19.5 | DI23: 19.3 | DJ23: 19.09 | DK23: 18.48 | DL23: 18.69 | DM23: 19.7 | DN23: 20.72 | DO23: 17.67 | DP23: 18.48 | DQ23: 18.28 | DR23: 24.58 | DS23: 36.88 | DT23: 51.53 | DU23: 57.84 | DV23: 58.72 | DW23: 57.5 | DX23: 54.98 | DY23: 52.42
B24: 20.05 | C24: 19.5 | D24: 21.12 | E24: 21.14 | F24: 19.7 | G24: 17.67 | H24: 15.64 | I24: 16.66 | J24: 19.3 | K24: 93.03 | L24: 230.69 | M24: 157.14 | N24: 162.7 | O24: 35.17 | P24: 21.33 | Q24: 24.58 | R24: 23.97 | S24: 24.38 | T24: 27.62 | U24: 26.81 | V24: 27.83 | W24: 27.62 | X24: 28.03 | Y24: 27.83 | Z24: 21.53 | AA24: 22.75 | AB24: 24.58 | AC24: 27.62 | AD24: 25.39 | AE24: 20.72 | AF24: 18.89 | AG24: 20.31 | AH24: 21.94 | AI24: 21.94 | AJ24: 22.75 | AK24: 17.67 | AL24: 18.28 | AM24: 20.11 | AN24: 20.31 | AO24: 24.58 | AP24: 27.42 | AQ24: 22.34 | AR24: 18.48 | AS24: 21.73 | AT24: 20.92 | AU24: 18.28 | AV24: 23.97 | AW24: 24.17 | AX24: 19.3 | AY24: 22.14 | AZ24: 21.53 | BA24: 19.3 | BB24: 20.11 | BC24: 20.52 | BD24: 18.89 | BE24: 17.67 | BF24: 17.88 | BG24: 23.36 | BH24: 45.22 | BI24: 83.64 | BJ24: 83.03 | BK24: 99.53 | BL24: 141.89 | BM24: 166.5 | BN24: 199.34 | BO24: 148.33 | BP24: 57.03 | BQ24: 22.14 | BR24: 20.92 | BS24: 16.25 | BT24: 17.47 | BU24: 16.66 | BV24: 17.27 | BW24: 19.7 | BX24: 19.3 | BY24: 20.11 | BZ24: 20.52 | CA24: 22.95 | CB24: 21.53 | CC24: 19.3 | CD24: 18.89 | CE24: 18.08 | CF24: 21.34 | CG24: 19.3 | CH24: 18.69 | CI24: 18.89 | CJ24: 18.89 | CK24: 20.52 | CL24: 23.36 | CM24: 25.8 | CN24: 27.02 | CO24: 26 | CP24: 25.39 | CQ24: 23.36 | CR24: 19.5 | CS24: 20.72 | CT24: 21.53 | CU24: 18.08 | CV24: 17.06 | CW24: 19.5 | CX24: 17.27 | CY24: 18.69 | CZ24: 17.88 | DA24: 17.27 | DB24: 17.47 | DC24: 20.11 | DD24: 19.7 | DE24: 17.67 | DF24: 20.31 | DG24: 19.5 | DH24: 20.52 | DI24: 18.69 | DJ24: 21.12 | DK24: 19.09 | DL24: 19.5 | DM24: 21.33 | DN24: 20.11 | DO24: 17.67 | DP24: 17.67 | DQ24: 20.92 | DR24: 29.86 | DS24: 64.95 | DT24: 71.81 | DU24: 67.2 | DV24: 48.69 | DW24: 39.44 | DX24: 31.69 | DY24: 29.77
B25: 19.44 | C25: 22.14 | D25: 22.14 | E25: 21.33 | F25: 20.52 | G25: 17.27 | H25: 15.23 | I25: 16.66 | J25: 17.06 | K25: 46.56 | L25: 223.17 | M25: 163.86 | N25: 156.84 | O25: 87.31 | P25: 26.44 | Q25: 22.95 | R25: 23.77 | S25: 29.45 | T25: 29.27 | U25: 28.64 | V25: 28.23 | W25: 25.59 | X25: 25.8 | Y25: 27.22 | Z25: 25.59 | AA25: 22.34 | AB25: 25.19 | AC25: 27.42 | AD25: 20.52 | AE25: 21.94 | AF25: 22.75 | AG25: 19.3 | AH25: 19.09 | AI25: 19.3 | AJ25: 19.7 | AK25: 18.89 | AL25: 19.09 | AM25: 20.72 | AN25: 20.72 | AO25: 24.38 | AP25: 26.81 | AQ25: 26.2 | AR25: 21.53 | AS25: 21.53 | AT25: 20.52 | AU25: 19.91 | AV25: 20.31 | AW25: 23.97 | AX25: 22.95 | AY25: 27.67 | AZ25: 21.33 | BA25: 21.73 | BB25: 20.92 | BC25: 20.92 | BD25: 20.11 | BE25: 20.11 | BF25: 23.56 | BG25: 45.02 | BH25: 84.69 | BI25: 88.47 | BJ25: 92.22 | BK25: 119.08 | BL25: 135.95 | BM25: 159.81 | BN25: 142.5 | BO25: 92.62 | BP25: 27.84 | BQ25: 21.73 | BR25: 18.89 | BS25: 17.27 | BT25: 19.3 | BU25: 16.66 | BV25: 18.08 | BW25: 21.33 | BX25: 20.72 | BY25: 19.7 | BZ25: 21.12 | CA25: 19.5 | CB25: 18.69 | CC25: 17.06 | CD25: 16.86 | CE25: 19.91 | CF25: 20.31 | CG25: 18.89 | CH25: 18.69 | CI25: 21.94 | CJ25: 21.33 | CK25: 23.16 | CL25: 23.56 | CM25: 26 | CN25: 27.03 | CO25: 26.61 | CP25: 25.39 | CQ25: 20.31 | CR25: 18.28 | CS25: 20.52 | CT25: 20.31 | CU25: 20.11 | CV25: 20.31 | CW25: 20.11 | CX25: 20.52 | CY25: 20.31 | CZ25: 20.52 | DA25: 19.3 | DB25: 21.73 | DC25: 22.14 | DD25: 20.52 | DE25: 19.5 | DF25: 19.91 | DG25: 21.12 | DH25: 19.09 | DI25: 19.09 | DJ25: 20.11 | DK25: 22.95 | DL25: 21.33 | DM25: 19.3 | DN25: 21.12 | DO25: 18.48 | DP25: 19.3 | DQ25: 18.28 | DR25: 31.33 | DS25: 70.72 | DT25: 68.73 | DU25: 37.66 | DV25: 23.77 | DW25: 22.14 | DX25: 20.72 | DY25: 19.44
A26: 6 | B26: 20.25 | C26: 20.11 | D26: 23.16 | E26: 21.94 | F26: 20.52 | G26: 17.06 | H26: 15.84 | I26: 16.45 | J26: 17.27 | K26: 34.38 | L26: 180.12 | M26: 193.41 | N26: 126.19 | O26: 182.23 | P26: 72.58 | Q26: 33.55 | R26: 24.38 | S26: 22.34 | T26: 24.38 | U26: 26.81 | V26: 23.16 | W26: 23.16 | X26: 24.98 | Y26: 23.97 | Z26: 24.17 | AA26: 18.89 | AB26: 20.11 | AC26: 21.73 | AD26: 21.33 | AE26: 19.5 | AF26: 19.3 | AG26: 18.89 | AH26: 20.72 | AI26: 19.3 | AJ26: 20.11 | AK26: 16.86 | AL26: 16.05 | AM26: 17.88 | AN26: 18.69 | AO26: 19.91 | AP26: 24.38 | AQ26: 22.55 | AR26: 20.52 | AS26: 23.16 | AT26: 24.58 | AU26: 23.98 | AV26: 24.38 | AW26: 26 | AX26: 22.34 | AY26: 20.92 | AZ26: 24.38 | BA26: 20.11 | BB26: 21.33 | BC26: 20.52 | BD26: 22.95 | BE26: 26 | BF26: 36.17 | BG26: 82.66 | BH26: 89.7 | BI26: 92.8 | BJ26: 118.25 | BK26: 124.95 | BL26: 93.48 | BM26: 116.97 | BN26: 100.31 | BO26: 57.84 | BP26: 27.88 | BQ26: 18.08 | BR26: 17.88 | BS26: 17.27 | BT26: 17.88 | BU26: 18.48 | BV26: 18.69 | BW26: 20.11 | BX26: 21.33 | BY26: 20.31 | BZ26: 20.52 | CA26: 19.5 | CB26: 18.48 | CC26: 18.69 | CD26: 18.28 | CE26: 16.86 | CF26: 20.11 | CG26: 19.7 | CH26: 22.95 | CI26: 22.34 | CJ26: 21.94 | CK26: 20.11 | CL26: 23.77 | CM26: 27.22 | CN26: 26 | CO26: 23.36 | CP26: 19.7 | CQ26: 19.5 | CR26: 17.67 | CS26: 18.28 | CT26: 18.89 | CU26: 21.12 | CV26: 24.58 | CW26: 24.17 | CX26: 20.72 | CY26: 23.77 | CZ26: 21.94 | DA26: 19.5 | DB26: 23.36 | DC26: 18.69 | DD26: 18.69 | DE26: 18.89 | DF26: 19.09 | DG26: 20.92 | DH26: 18.69 | DI26: 19.3 | DJ26: 19.91 | DK26: 18.69 | DL26: 19.7 | DM26: 18.69 | DN26: 18.28 | DO26: 20.72 | DP26: 18.28 | DQ26: 20.52 | DR26: 35.22 | DS26: 67.64 | DT26: 49.12 | DU26: 22.14 | DV26: 19.3 | DW26: 20.72 | DX26: 19.3 | DY26: 20.66
B27: 19.02 | C27: 21.12 | D27: 23.97 | E27: 22.34 | F27: 21.53 | G27: 17.67 | H27: 15.64 | I27: 16.45 | J27: 18.3 | K27: 27.83 | L27: 175.86 | M27: 185.38 | N27: 133.75 | O27: 164.33 | P27: 132.58 | Q27: 66.58 | R27: 25.59 | S27: 21.94 | T27: 24.38 | U27: 21.94 | V27: 20.31 | W27: 21.33 | X27: 22.95 | Y27: 21.73 | Z27: 19.3 | AA27: 19.09 | AB27: 23.97 | AC27: 21.55 | AD27: 18.69 | AE27: 19.5 | AF27: 19.7 | AG27: 19.5 | AH27: 18.69 | AI27: 21.12 | AJ27: 25 | AK27: 19.09 | AL27: 17.06 | AM27: 16.86 | AN27: 19.7 | AO27: 18.89 | AP27: 18.08 | AQ27: 21.94 | AR27: 23.77 | AS27: 19.91 | AT27: 24.38 | AU27: 27.62 | AV27: 24.78 | AW27: 24.17 | AX27: 23.16 | AY27: 25.61 | AZ27: 31.09 | BA27: 29.05 | BB27: 21.33 | BC27: 22.95 | BD27: 27.62 | BE27: 30.67 | BF27: 63.59 | BG27: 81.19 | BH27: 83.47 | BI27: 116.19 | BJ27: 108.45 | BK27: 105.97 | BL27: 94.95 | BM27: 96.12 | BN27: 109.47 | BO27: 36.48 | BP27: 21.33 | BQ27: 19.5 | BR27: 15.84 | BS27: 16.66 | BT27: 19.09 | BU27: 17.47 | BV27: 18.89 | BW27: 19.91 | BX27: 21.33 | BY27: 21.12 | BZ27: 19.3 | CA27: 19.3 | CB27: 16.45 | CC27: 20.11 | CD27: 19.5 | CE27: 20.11 | CF27: 21.53 | CG27: 20.31 | CH27: 22.14 | CI27: 21.33 | CJ27: 20.72 | CK27: 18.89 | CL27: 22.95 | CM27: 29.86 | CN27: 23.56 | CO27: 19.91 | CP27: 16.66 | CQ27: 19.3 | CR27: 19.09 | CS27: 19.3 | CT27: 22.95 | CU27: 20.92 | CV27: 24.98 | CW27: 25.59 | CX27: 25.81 | CY27: 23.77 | CZ27: 22.14 | DA27: 19.91 | DB27: 21.53 | DC27: 20.92 | DD27: 19.09 | DE27: 18.89 | DF27: 18.48 | DG27: 19.09 | DH27: 21.12 | DI27: 20.92 | DJ27: 20.92 | DK27: 18.48 | DL27: 19.09 | DM27: 20.72 | DN27: 19.5 | DO27: 19.7 | DP27: 18.08 | DQ27: 22.95 | DR27: 33.97 | DS27: 66.12 | DT27: 40.75 | DU27: 22.14 | DV27: 22.75 | DW27: 20.31 | DX27: 20.11 | DY27: 19.44
B28: 18.83 | C28: 20.92 | D28: 20.31 | E28: 24.8 | F28: 21.73 | G28: 20.92 | H28: 16.86 | I28: 17.06 | J28: 18.08 | K28: 27.22 | L28: 170.5 | M28: 156.77 | N28: 155.08 | O28: 142.69 | P28: 151.83 | Q28: 41.56 | R28: 24.38 | S28: 22.95 | T28: 21.53 | U28: 22.34 | V28: 23.97 | W28: 22.14 | X28: 23.36 | Y28: 22.36 | Z28: 26.41 | AA28: 25.59 | AB28: 24.61 | AC28: 23.97 | AD28: 22.75 | AE28: 21.53 | AF28: 22.97 | AG28: 21.33 | AH28: 18.48 | AI28: 17.27 | AJ28: 19.5 | AK28: 20.52 | AL28: 19.5 | AM28: 17.27 | AN28: 18.08 | AO28: 17.47 | AP28: 18.28 | AQ28: 19.7 | AR28: 19.09 | AS28: 22.34 | AT28: 24.38 | AU28: 23.16 | AV28: 22.75 | AW28: 21.94 | AX28: 22.55 | AY28: 25.39 | AZ28: 32.52 | BA28: 31.48 | BB28: 27.42 | BC28: 33.12 | BD28: 33.33 | BE28: 51.34 | BF28: 89.88 | BG28: 102.42 | BH28: 106.38 | BI28: 106.16 | BJ28: 91.17 | BK28: 96.59 | BL28: 103.27 | BM28: 90.95 | BN28: 92.2 | BO28: 29.27 | BP28: 17.27 | BQ28: 19.5 | BR28: 16.45 | BS28: 15.03 | BT28: 17.27 | BU28: 16.86 | BV28: 18.89 | BW28: 18.69 | BX28: 17.47 | BY28: 19.3 | BZ28: 19.5 | CA28: 21.73 | CB28: 21.73 | CC28: 24.38 | CD28: 21.33 | CE28: 19.3 | CF28: 20.92 | CG28: 19.91 | CH28: 24.8 | CI28: 19.7 | CJ28: 22.95 | CK28: 21.73 | CL28: 30.06 | CM28: 30.47 | CN28: 21.94 | CO28: 22.14 | CP28: 19.91 | CQ28: 21.94 | CR28: 21.53 | CS28: 21.33 | CT28: 18.28 | CU28: 19.91 | CV28: 22.34 | CW28: 25.8 | CX28: 27.22 | CY28: 32.36 | CZ28: 25.59 | DA28: 22.34 | DB28: 21.12 | DC28: 20.31 | DD28: 20.31 | DE28: 19.7 | DF28: 19.3 | DG28: 15.84 | DH28: 19.7 | DI28: 19.5 | DJ28: 18.28 | DK28: 19.09 | DL28: 18.69 | DM28: 20.92 | DN28: 18.69 | DO28: 21.33 | DP28: 24.38 | DQ28: 31.11 | DR28: 54.31 | DS28: 82 | DT28: 31.5 | DU28: 19.5 | DV28: 22.14 | DW28: 19.7 | DX28: 18.69 | DY28: 20.45
B29: 20.64 | C29: 21.73 | D29: 22.75 | E29: 23.97 | F29: 24.78 | G29: 19.5 | H29: 16.45 | I29: 18.08 | J29: 19.5 | K29: 24.78 | L29: 172.44 | M29: 156.94 | N29: 164.64 | O29: 161.55 | P29: 151.44 | Q29: 29.88 | R29: 21.53 | S29: 21.53 | T29: 21.73 | U29: 22.75 | V29: 22.95 | W29: 22.75 | X29: 21.73 | Y29: 22.14 | Z29: 24.17 | AA29: 22.55 | AB29: 24.17 | AC29: 21.94 | AD29: 21.73 | AE29: 22.34 | AF29: 21.53 | AG29: 21.33 | AH29: 20.31 | AI29: 19.7 | AJ29: 17.47 | AK29: 16.66 | AL29: 18.08 | AM29: 17.67 | AN29: 16.66 | AO29: 18.48 | AP29: 21.73 | AQ29: 19.09 | AR29: 26.62 | AS29: 22.14 | AT29: 23.36 | AU29: 23.97 | AV29: 21.73 | AW29: 27.02 | AX29: 25.19 | AY29: 23.97 | AZ29: 29.86 | BA29: 31.5 | BB29: 35.56 | BC29: 37.61 | BD29: 42.52 | BE29: 73.08 | BF29: 105.48 | BG29: 122.45 | BH29: 87.02 | BI29: 82.2 | BJ29: 78.45 | BK29: 101.62 | BL29: 89.69 | BM29: 95.77 | BN29: 96.58 | BO29: 32.11 | BP29: 17.67 | BQ29: 16.66 | BR29: 18.08 | BS29: 15.44 | BT29: 15.03 | BU29: 17.47 | BV29: 19.5 | BW29: 20.31 | BX29: 18.69 | BY29: 20.72 | BZ29: 20.52 | CA29: 23.16 | CB29: 20.11 | CC29: 23.16 | CD29: 19.91 | CE29: 20.31 | CF29: 22.95 | CG29: 21.53 | CH29: 20.52 | CI29: 19.5 | CJ29: 21.12 | CK29: 24.98 | CL29: 31.08 | CM29: 24.17 | CN29: 24.17 | CO29: 21.53 | CP29: 22.55 | CQ29: 22.34 | CR29: 22.14 | CS29: 21.73 | CT29: 21.33 | CU29: 18.89 | CV29: 19.3 | CW29: 24.17 | CX29: 25.8 | CY29: 25.59 | CZ29: 21.73 | DA29: 19.5 | DB29: 18.48 | DC29: 18.89 | DD29: 19.7 | DE29: 17.67 | DF29: 19.7 | DG29: 17.47 | DH29: 17.47 | DI29: 19.09 | DJ29: 19.7 | DK29: 19.5 | DL29: 20.31 | DM29: 20.52 | DN29: 23.17 | DO29: 28.05 | DP29: 49.89 | DQ29: 55.05 | DR29: 56.67 | DS29: 52.66 | DT29: 23.97 | DU29: 19.91 | DV29: 17.47 | DW29: 19.09 | DX29: 24.39 | DY29: 24.48
A30: 7 | B30: 21.06 | C30: 18.08 | D30: 21.12 | E30: 23.97 | F30: 23.36 | G30: 23.56 | H30: 19.3 | I30: 19.52 | J30: 16.45 | K30: 21.94 | L30: 122.98 | M30: 141.59 | N30: 162.88 | O30: 197.23 | P30: 155.34 | Q30: 27.62 | R30: 19.7 | S30: 19.5 | T30: 18.08 | U30: 19.5 | V30: 22.95 | W30: 19.7 | X30: 22.14 | Y30: 21.94 | Z30: 19.3 | AA30: 19.5 | AB30: 21.75 | AC30: 21.33 | AD30: 20.92 | AE30: 21.73 | AF30: 21.53 | AG30: 24.17 | AH30: 22.55 | AI30: 22.75 | AJ30: 21.33 | AK30: 18.89 | AL30: 21.12 | AM30: 20.31 | AN30: 18.08 | AO30: 19.91 | AP30: 20.11 | AQ30: 22.75 | AR30: 21.53 | AS30: 23.77 | AT30: 25.39 | AU30: 25.19 | AV30: 28.03 | AW30: 26.2 | AX30: 27.02 | AY30: 29.25 | AZ30: 32.72 | BA30: 35.56 | BB30: 39.2 | BC30: 44.11 | BD30: 73.27 | BE30: 112 | BF30: 106.59 | BG30: 86.83 | BH30: 75.3 | BI30: 75.53 | BJ30: 99.95 | BK30: 101.19 | BL30: 90.3 | BM30: 101.19 | BN30: 113.67 | BO30: 36.88 | BP30: 17.88 | BQ30: 17.27 | BR30: 16.66 | BS30: 16.05 | BT30: 15.23 | BU30: 19.3 | BV30: 20.31 | BW30: 22.55 | BX30: 23.56 | BY30: 22.75 | BZ30: 24.38 | CA30: 26.2 | CB30: 22.14 | CC30: 19.09 | CD30: 20.31 | CE30: 21.53 | CF30: 18.08 | CG30: 22.77 | CH30: 20.92 | CI30: 21.33 | CJ30: 19.91 | CK30: 23.77 | CL30: 27.02 | CM30: 22.75 | CN30: 20.11 | CO30: 20.72 | CP30: 22.16 | CQ30: 28.48 | CR30: 22.55 | CS30: 20.52 | CT30: 21.73 | CU30: 21.53 | CV30: 23.97 | CW30: 22.95 | CX30: 26.41 | CY30: 23.16 | CZ30: 19.09 | DA30: 21.12 | DB30: 21.53 | DC30: 18.48 | DD30: 21.33 | DE30: 20.92 | DF30: 18.69 | DG30: 18.69 | DH30: 18.08 | DI30: 17.47 | DJ30: 17.47 | DK30: 21.94 | DL30: 17.88 | DM30: 21.94 | DN30: 34.16 | DO30: 41.06 | DP30: 50.03 | DQ30: 46.59 | DR30: 47.77 | DS30: 27.22 | DT30: 23.16 | DU30: 19.7 | DV30: 16.66 | DW30: 17.67 | DX30: 42.38 | DY30: 25.34
B31: 21.45 | C31: 22.75 | D31: 23.16 | E31: 26.81 | F31: 26.61 | G31: 27.22 | H31: 22.55 | I31: 18.48 | J31: 19.91 | K31: 21.94 | L31: 62.09 | M31: 148.44 | N31: 162.64 | O31: 183.39 | P31: 154.78 | Q31: 24.98 | R31: 21.53 | S31: 21.33 | T31: 17.47 | U31: 17.06 | V31: 15.84 | W31: 17.27 | X31: 20.73 | Y31: 18.69 | Z31: 19.7 | AA31: 16.25 | AB31: 16.05 | AC31: 18.08 | AD31: 16.86 | AE31: 19.09 | AF31: 19.3 | AG31: 21.73 | AH31: 21.33 | AI31: 21.53 | AJ31: 23.36 | AK31: 23.36 | AL31: 30.3 | AM31: 19.91 | AN31: 19.3 | AO31: 19.7 | AP31: 21.12 | AQ31: 20.72 | AR31: 21.33 | AS31: 22.75 | AT31: 24.78 | AU31: 25.8 | AV31: 26.81 | AW31: 32.7 | AX31: 39.25 | AY31: 56.95 | AZ31: 66.5 | BA31: 72.25 | BB31: 84.77 | BC31: 103.42 | BD31: 134.86 | BE31: 114.3 | BF31: 93.88 | BG31: 89.69 | BH31: 84.06 | BI31: 76.11 | BJ31: 81.19 | BK31: 96.8 | BL31: 86.03 | BM31: 76.36 | BN31: 80.56 | BO31: 38.67 | BP31: 19.3 | BQ31: 18.89 | BR31: 19.5 | BS31: 15.44 | BT31: 16.66 | BU31: 17.67 | BV31: 19.09 | BW31: 21.33 | BX31: 21.73 | BY31: 20.92 | BZ31: 21.53 | CA31: 22.95 | CB31: 21.94 | CC31: 20.72 | CD31: 21.12 | CE31: 21.33 | CF31: 22.14 | CG31: 22.95 | CH31: 20.31 | CI31: 20.52 | CJ31: 22.14 | CK31: 25.39 | CL31: 24.58 | CM31: 20.11 | CN31: 20.72 | CO31: 21.12 | CP31: 24.98 | CQ31: 27.44 | CR31: 26.62 | CS31: 21.94 | CT31: 23.97 | CU31: 24.58 | CV31: 23.97 | CW31: 23.36 | CX31: 22.95 | CY31: 21.12 | CZ31: 19.7 | DA31: 17.88 | DB31: 18.69 | DC31: 20.72 | DD31: 20.11 | DE31: 18.69 | DF31: 21.73 | DG31: 18.69 | DH31: 19.31 | DI31: 19.5 | DJ31: 19.91 | DK31: 18.69 | DL31: 20.52 | DM31: 33.72 | DN31: 44.75 | DO31: 42.28 | DP31: 38.61 | DQ31: 44.77 | DR31: 32.11 | DS31: 20.52 | DT31: 19.91 | DU31: 19.5 | DV31: 17.88 | DW31: 18.89 | DX31: 28.89 | DY31: 21.45
B32: 23.3 | C32: 53.2 | D32: 85.09 | E32: 54.95 | F32: 48.53 | G32: 67.78 | H32: 70.5 | I32: 53.05 | J32: 24.38 | K32: 24.78 | L32: 54.53 | M32: 156.16 | N32: 178.41 | O32: 195.19 | P32: 126.95 | Q32: 22.55 | R32: 22.34 | S32: 18.69 | T32: 18.28 | U32: 17.67 | V32: 18.28 | W32: 17.27 | X32: 18.08 | Y32: 16.45 | Z32: 19.7 | AA32: 17.27 | AB32: 17.27 | AC32: 18.89 | AD32: 17.88 | AE32: 16.66 | AF32: 16.86 | AG32: 17.27 | AH32: 18.69 | AI32: 19.7 | AJ32: 24.17 | AK32: 31.14 | AL32: 29.11 | AM32: 23.16 | AN32: 21.73 | AO32: 24.78 | AP32: 23.36 | AQ32: 21.73 | AR32: 24.17 | AS32: 23.77 | AT32: 29.25 | AU32: 30.67 | AV32: 44.78 | AW32: 70.81 | AX32: 91.61 | AY32: 126.62 | AZ32: 148.72 | BA32: 166.45 | BB32: 174.48 | BC32: 148.02 | BD32: 108.02 | BE32: 110.11 | BF32: 109.31 | BG32: 83.28 | BH32: 85.48 | BI32: 90.52 | BJ32: 72.09 | BK32: 80.47 | BL32: 100.97 | BM32: 92.19 | BN32: 76.39 | BO32: 40.73 | BP32: 19.7 | BQ32: 17.67 | BR32: 18.48 | BS32: 16.86 | BT32: 18.28 | BU32: 18.09 | BV32: 18.08 | BW32: 17.88 | BX32: 21.12 | BY32: 17.88 | BZ32: 21.94 | CA32: 21.94 | CB32: 21.73 | CC32: 20.72 | CD32: 24.58 | CE32: 22.34 | CF32: 19.7 | CG32: 19.7 | CH32: 21.12 | CI32: 21.33 | CJ32: 23.97 | CK32: 21.94 | CL32: 23.16 | CM32: 19.5 | CN32: 20.11 | CO32: 23.36 | CP32: 24.38 | CQ32: 21.33 | CR32: 21.94 | CS32: 22.55 | CT32: 23.56 | CU32: 23.77 | CV32: 20.72 | CW32: 24.17 | CX32: 19.09 | CY32: 17.88 | CZ32: 19.7 | DA32: 18.89 | DB32: 19.7 | DC32: 18.28 | DD32: 17.47 | DE32: 20.52 | DF32: 18.28 | DG32: 19.5 | DH32: 18.89 | DI32: 17.88 | DJ32: 19.7 | DK32: 19.91 | DL32: 32.72 | DM32: 49.64 | DN32: 46.42 | DO32: 41.06 | DP32: 39.23 | DQ32: 34.58 | DR32: 20.31 | DS32: 17.47 | DT32: 17.67 | DU32: 17.88 | DV32: 17.06 | DW32: 18.69 | DX32: 20.11 | DY32: 19.23
B33: 24.52 | C33: 112.45 | D33: 210.22 | E33: 220.47 | F33: 200.8 | G33: 158.2 | H33: 137.06 | I33: 133.86 | J33: 97.97 | K33: 29.45 | L33: 51.39 | M33: 123.03 | N33: 178.81 | O33: 207.16 | P33: 115.59 | Q33: 26.81 | R33: 21.53 | S33: 20.31 | T33: 18.69 | U33: 17.67 | V33: 17.06 | W33: 16.05 | X33: 18.48 | Y33: 18.89 | Z33: 20.31 | AA33: 21.33 | AB33: 20.31 | AC33: 17.67 | AD33: 16.86 | AE33: 16.86 | AF33: 21.94 | AG33: 16.86 | AH33: 16.66 | AI33: 15.84 | AJ33: 16.66 | AK33: 22.14 | AL33: 25.59 | AM33: 22.34 | AN33: 21.94 | AO33: 26.84 | AP33: 27.83 | AQ33: 24.98 | AR33: 27.42 | AS33: 31.3 | AT33: 53.52 | AU33: 80.33 | AV33: 102.16 | AW33: 120.58 | AX33: 131.62 | AY33: 150.94 | AZ33: 163.5 | BA33: 170.55 | BB33: 146.41 | BC33: 120.94 | BD33: 124.5 | BE33: 133.28 | BF33: 106.33 | BG33: 97.83 | BH33: 96.16 | BI33: 97.22 | BJ33: 94.92 | BK33: 89.06 | BL33: 113.86 | BM33: 109.11 | BN33: 103.38 | BO33: 65.98 | BP33: 18.89 | BQ33: 19.3 | BR33: 16.66 | BS33: 17.47 | BT33: 16.66 | BU33: 16.86 | BV33: 18.48 | BW33: 18.89 | BX33: 17.88 | BY33: 18.08 | BZ33: 20.52 | CA33: 20.11 | CB33: 21.53 | CC33: 23.58 | CD33: 25.39 | CE33: 25.39 | CF33: 22.14 | CG33: 20.92 | CH33: 22.14 | CI33: 24.78 | CJ33: 22.55 | CK33: 22.95 | CL33: 25.39 | CM33: 19.09 | CN33: 21.12 | CO33: 24.17 | CP33: 21.73 | CQ33: 19.91 | CR33: 19.09 | CS33: 19.09 | CT33: 20.72 | CU33: 21.73 | CV33: 21.94 | CW33: 20.72 | CX33: 19.3 | CY33: 18.48 | CZ33: 15.84 | DA33: 17.47 | DB33: 17.47 | DC33: 20.72 | DD33: 20.11 | DE33: 18.28 | DF33: 18.89 | DG33: 16.45 | DH33: 17.47 | DI33: 17.06 | DJ33: 19.09 | DK33: 25.2 | DL33: 45.61 | DM33: 41.48 | DN33: 44.7 | DO33: 49.25 | DP33: 53.27 | DQ33: 23.77 | DR33: 18.89 | DS33: 16.25 | DT33: 15.64 | DU33: 15.64 | DV33: 15.23 | DW33: 16.05 | DX33: 20.92 | DY33: 16.59
A34: 8 | B34: 18.22 | C34: 32.8 | D34: 80.17 | E34: 182.36 | F34: 237.33 | G34: 244.73 | H34: 224.3 | I34: 164.8 | J34: 198.61 | K34: 120.81 | L34: 58.42 | M34: 103.69 | N34: 186.34 | O34: 204.05 | P34: 113.39 | Q34: 22.75 | R34: 18.69 | S34: 18.69 | T34: 17.06 | U34: 16.25 | V34: 17.67 | W34: 18.08 | X34: 15.23 | Y34: 19.09 | Z34: 21.53 | AA34: 18.08 | AB34: 22.14 | AC34: 18.89 | AD34: 17.88 | AE34: 15.84 | AF34: 16.05 | AG34: 15.23 | AH34: 15.84 | AI34: 17.06 | AJ34: 17.67 | AK34: 16.05 | AL34: 19.09 | AM34: 21.94 | AN34: 21.53 | AO34: 26 | AP34: 30.69 | AQ34: 41.75 | AR34: 58.69 | AS34: 80.77 | AT34: 104.92 | AU34: 143.67 | AV34: 146.19 | AW34: 127.02 | AX34: 120.77 | AY34: 94.92 | AZ34: 114.52 | BA34: 114.45 | BB34: 113.92 | BC34: 113.06 | BD34: 103.62 | BE34: 127.84 | BF34: 119.48 | BG34: 93.45 | BH34: 80.25 | BI34: 71.38 | BJ34: 110.77 | BK34: 104.75 | BL34: 100.98 | BM34: 116.58 | BN34: 107.81 | BO34: 96.02 | BP34: 27.66 | BQ34: 19.7 | BR34: 17.88 | BS34: 17.06 | BT34: 18.28 | BU34: 18.69 | BV34: 18.69 | BW34: 17.06 | BX34: 19.09 | BY34: 18.69 | BZ34: 20.92 | CA34: 21.33 | CB34: 20.92 | CC34: 21.12 | CD34: 23.97 | CE34: 24.17 | CF34: 20.52 | CG34: 21.33 | CH34: 21.33 | CI34: 26 | CJ34: 23.97 | CK34: 24.78 | CL34: 24.58 | CM34: 22.34 | CN34: 19.5 | CO34: 23.77 | CP34: 19.7 | CQ34: 19.3 | CR34: 20.11 | CS34: 21.12 | CT34: 29.25 | CU34: 52.8 | CV34: 36.03 | CW34: 24.58 | CX34: 18.89 | CY34: 19.5 | CZ34: 19.7 | DA34: 17.67 | DB34: 17.88 | DC34: 19.3 | DD34: 16.25 | DE34: 17.27 | DF34: 16.25 | DG34: 17.67 | DH34: 17.88 | DI34: 21.33 | DJ34: 20.52 | DK34: 43.38 | DL34: 41.86 | DM34: 42.7 | DN34: 53.03 | DO34: 57.5 | DP34: 30.73 | DQ34: 20.31 | DR34: 17.06 | DS34: 17.47 | DT34: 17.27 | DU34: 16.66 | DV34: 17.89 | DW34: 20.52 | DX34: 18.48 | DY34: 20.23
B35: 21.05 | C35: 24.17 | D35: 26.62 | E35: 84.7 | F35: 178.48 | G35: 197.34 | H35: 239.14 | I35: 232.09 | J35: 214.16 | K35: 217.84 | L35: 174.14 | M35: 162.22 | N35: 193.16 | O35: 208.09 | P35: 77.16 | Q35: 23.97 | R35: 21.12 | S35: 19.3 | T35: 19.91 | U35: 17.67 | V35: 17.67 | W35: 18.48 | X35: 16.66 | Y35: 16.86 | Z35: 17.27 | AA35: 18.48 | AB35: 19.3 | AC35: 21.12 | AD35: 19.91 | AE35: 19.09 | AF35: 16.66 | AG35: 16.47 | AH35: 15.64 | AI35: 17.47 | AJ35: 18.28 | AK35: 18.89 | AL35: 20.52 | AM35: 24.17 | AN35: 35.58 | AO35: 59.11 | AP35: 75.12 | AQ35: 95.77 | AR35: 115.52 | AS35: 130.06 | AT35: 128.91 | AU35: 134.92 | AV35: 124.53 | AW35: 119.53 | AX35: 98.41 | AY35: 92.84 | AZ35: 100.06 | BA35: 107.91 | BB35: 121.8 | BC35: 107.59 | BD35: 99.91 | BE35: 92 | BF35: 108.06 | BG35: 98.73 | BH35: 67.39 | BI35: 74.89 | BJ35: 93.88 | BK35: 113.31 | BL35: 91.77 | BM35: 100.12 | BN35: 127.16 | BO35: 111.8 | BP35: 66.12 | BQ35: 26 | BR35: 18.69 | BS35: 17.47 | BT35: 17.67 | BU35: 16.86 | BV35: 19.3 | BW35: 18.48 | BX35: 20.92 | BY35: 22.14 | BZ35: 19.09 | CA35: 18.69 | CB35: 16.66 | CC35: 20.11 | CD35: 19.91 | CE35: 18.69 | CF35: 21.33 | CG35: 24.17 | CH35: 23.97 | CI35: 24.58 | CJ35: 21.33 | CK35: 28.64 | CL35: 26 | CM35: 22.55 | CN35: 20.52 | CO35: 20.72 | CP35: 20.72 | CQ35: 23.36 | CR35: 28.05 | CS35: 72.73 | CT35: 137.12 | CU35: 150.83 | CV35: 136.73 | CW35: 55.38 | CX35: 38.27 | CY35: 43.48 | CZ35: 25.8 | DA35: 25.39 | DB35: 22.75 | DC35: 19.5 | DD35: 16.86 | DE35: 18.69 | DF35: 17.67 | DG35: 17.88 | DH35: 20.31 | DI35: 20.31 | DJ35: 30.7 | DK35: 49.91 | DL35: 44.11 | DM35: 55.03 | DN35: 56.62 | DO35: 32.12 | DP35: 19.7 | DQ35: 20.72 | DR35: 21.33 | DS35: 17.88 | DT35: 18.48 | DU35: 17.06 | DV35: 19.09 | DW35: 20.92 | DX35: 18.08 | DY35: 24.52
